Workbook

Sheet Resumen Mensual
A1: POWER Digital® — Arauco Premium Outlet Buenaventura — Consumo por Local y Mes
A2: Outlet 70 medidores | 70 medidores | Año 2025 | Peak Hora Punta: 18:00 – 22:00
A3: Mes | B3: N° Mes | C3: Ubicación | D3: ID Medidor | E3: Tipo Local | F3: Nombre Local | G3: Fase | H3: Consumo Mensual (kWh) | I3: Peak Mensual (kW) | J3: Demanda Hora Punta (kWh) | K3: % Punta / Consumo Total | L3: Promedio Diario (kWh) | M3: Consumo Energía ($kWh) | N3: Dda. Máx. Suministrada(kW) | O3: Dda. Máx. Hora Punta(kW) | P3: KWH para Sistema Troncal | Q3: KWH para Serv. Público Neto | R3: Cargo Fijo ($) | S3: Total Neto($) | T3: IVA ($) | U3: Monto Exento | V3: Total con IVA ($)
A4: Enero | B4: 1 | C4: Arauco Premium Outlet Buenaventura | D4: OT-001 | E4: SSCC | F4: Servicios comunes | G4: 3P | H4: 12723.736 | I4: 34.0904 | J4: 34.0904 | K4: 1 | L4: 410.44 | M4: =H4*INDEX('Pliegos Tarifarios (Quilicura)'!$B:$B,MATCH($B4,'Pliegos Tarifarios (Quilicura)'!$A:$A,0)) -> 1512063.3 | N4: =I4*INDEX('Pliegos Tarifarios (Quilicura)'!$C:$C,MATCH($B4,'Pliegos Tarifarios (Quilicura)'!$A:$A,0)) -> 116422.43 | O4: =J4*INDEX('Pliegos Tarifarios (Quilicura)'!$D:$D,MATCH($B4,'Pliegos Tarifarios (Quilicura)'!$A:$A,0)) -> 480899.81 | P4: =H4*INDEX('Pliegos Tarifarios (Quilicura)'!$E:$E,MATCH($B4,'Pliegos Tarifarios (Quilicura)'!$A:$A,0)) -> 164543.35 | Q4: {=H4*_xlfn.IFS(H4<=350,INDEX('Pliegos Tarifarios (Quilicura)'!$F:$F,MATCH($B4,'Pliegos Tarifarios (Quilicura)'!$A:$A,0)),H4<=500,INDEX('Pliegos Tarifarios (Quilicura)'!$G:$G,MATCH($B4,'Pliegos Tarifarios (Quilicura)'!$A:$A,0)),H4<=1000,INDEX('Pliegos Tarifarios (Quilicura)'!$H:$H,MATCH($B4,'Pliegos Tarifarios (Quilicura)'!$A:$A,0)),H4<=5000,INDEX('Pliegos Tarifarios (Quilicura)'!$I:$I,MATCH($B4,'Pliegos Tarifarios (Quilicura)'!$A:$A,0)),H4>5000,INDEX('Pliegos Tarifarios (Quilicura)'!$J:$J,MATCH($B4,'Pliegos Tarifarios (Quilicura)'!$A:$A,0)))/1.19} -> 41753.098 | R4: =INDEX('Pliegos Tarifarios (Quilicura)'!$K:$K,MATCH($B4,'Pliegos Tarifarios (Quilicura)'!$A:$A,0)) -> 710.782 | S4: =SUM(M4:R4) -> 2316392.7 | T4: =S4*0.19 -> 440114.62 | U4: 0 | V4: =SUM(S4:T4) -> 2756507.4
A5: Enero | B5: 1 | C5: Arauco Premium Outlet Buenaventura | D5: OT-002 | E5: Retail | F5: Supermercado | G5: 3P | H5: 6360.7311 | I5: 16.9515 | J5: 16.9315 | K5: 0.99882016 | L5: 205.18 | M5: =H5*INDEX('Pliegos Tarifarios (Quilicura)'!$B:$B,MATCH($B5,'Pliegos Tarifarios (Quilicura)'!$A:$A,0)) -> 755896.56 | N5: =I5*INDEX('Pliegos Tarifarios (Quilicura)'!$C:$C,MATCH($B5,'Pliegos Tarifarios (Quilicura)'!$A:$A,0)) -> 57891.22 | O5: =J5*INDEX('Pliegos Tarifarios (Quilicura)'!$D:$D,MATCH($B5,'Pliegos Tarifarios (Quilicura)'!$A:$A,0)) -> 238845.98 | P5: =H5*INDEX('Pliegos Tarifarios (Quilicura)'!$E:$E,MATCH($B5,'Pliegos Tarifarios (Quilicura)'!$A:$A,0)) -> 82256.975 | Q5: {=H5*_xlfn.IFS(H5<=350,INDEX('Pliegos Tarifarios (Quilicura)'!$F:$F,MATCH($B5,'Pliegos Tarifarios (Quilicura)'!$A:$A,0)),H5<=500,INDEX('Pliegos Tarifarios (Quilicura)'!$G:$G,MATCH($B5,'Pliegos Tarifarios (Quilicura)'!$A:$A,0)),H5<=1000,INDEX('Pliegos Tarifarios (Quilicura)'!$H:$H,MATCH($B5,'Pliegos Tarifarios (Quilicura)'!$A:$A,0)),H5<=5000,INDEX('Pliegos Tarifarios (Quilicura)'!$I:$I,MATCH($B5,'Pliegos Tarifarios (Quilicura)'!$A:$A,0)),H5>5000,INDEX('Pliegos Tarifarios (Quilicura)'!$J:$J,MATCH($B5,'Pliegos Tarifarios (Quilicura)'!$A:$A,0)))/1.19} -> 20872.819 | R5: =INDEX('Pliegos Tarifarios (Quilicura)'!$K:$K,MATCH($B5,'Pliegos Tarifarios (Quilicura)'!$A:$A,0)) -> 710.782 | S5: =SUM(M5:R5) -> 1156474.3 | T5: =S5*0.19 -> 219730.12 | U5: 0 | V5: =SUM(S5:T5) -> 1376204.5
A6: Enero | B6: 1 | C6: Arauco Premium Outlet Buenaventura | D6: OT-003 | E6: Retail | F6: supermercado2 | G6: 3P | H6: 5082.9563 | I6: 13.4517 | J6: 13.4517 | K6: 1 | L6: 163.97 | M6: =H6*INDEX('Pliegos Tarifarios (Quilicura)'!$B:$B,MATCH($B6,'Pliegos Tarifarios (Quilicura)'!$A:$A,0)) -> 604048.36 | N6: =I6*INDEX('Pliegos Tarifarios (Quilicura)'!$C:$C,MATCH($B6,'Pliegos Tarifarios (Quilicura)'!$A:$A,0)) -> 45939.022 | O6: =J6*INDEX('Pliegos Tarifarios (Quilicura)'!$D:$D,MATCH($B6,'Pliegos Tarifarios (Quilicura)'!$A:$A,0)) -> 189757.82 | P6: =H6*INDEX('Pliegos Tarifarios (Quilicura)'!$E:$E,MATCH($B6,'Pliegos Tarifarios (Quilicura)'!$A:$A,0)) -> 65732.791 | Q6: {=H6*_xlfn.IFS(H6<=350,INDEX('Pliegos Tarifarios (Quilicura)'!$F:$F,MATCH($B6,'Pliegos Tarifarios (Quilicura)'!$A:$A,0)),H6<=500,INDEX('Pliegos Tarifarios (Quilicura)'!$G:$G,MATCH($B6,'Pliegos Tarifarios (Quilicura)'!$A:$A,0)),H6<=1000,INDEX('Pliegos Tarifarios (Quilicura)'!$H:$H,MATCH($B6,'Pliegos Tarifarios (Quilicura)'!$A:$A,0)),H6<=5000,INDEX('Pliegos Tarifarios (Quilicura)'!$I:$I,MATCH($B6,'Pliegos Tarifarios (Quilicura)'!$A:$A,0)),H6>5000,INDEX('Pliegos Tarifarios (Quilicura)'!$J:$J,MATCH($B6,'Pliegos Tarifarios (Quilicura)'!$A:$A,0)))/1.19} -> 16679.785 | R6: =INDEX('Pliegos Tarifarios (Quilicura)'!$K:$K,MATCH($B6,'Pliegos Tarifarios (Quilicura)'!$A:$A,0)) -> 710.782 | S6: =SUM(M6:R6) -> 922868.56 | T6: =S6*0.19 -> 175345.03 | U6: 0 | V6: =SUM(S6:T6) -> 1098213.6
A7: Enero | B7: 1 | C7: Arauco Premium Outlet Buenaventura | D7: OT-004 | E7: Retail | F7: Ripley | G7: 3P | H7: 4242.5761 | I7: 11.14 | J7: 11.0703 | K7: 0.99374327 | L7: 136.86 | M7: =H7*INDEX('Pliegos Tarifarios (Quilicura)'!$B:$B,MATCH($B7,'Pliegos Tarifarios (Quilicura)'!$A:$A,0)) -> 504179.26 | N7: =I7*INDEX('Pliegos Tarifarios (Quilicura)'!$C:$C,MATCH($B7,'Pliegos Tarifarios (Quilicura)'!$A:$A,0)) -> 38044.314 | O7: =J7*INDEX('Pliegos Tarifarios (Quilicura)'!$D:$D,MATCH($B7,'Pliegos Tarifarios (Quilicura)'!$A:$A,0)) -> 156164.35 | P7: =H7*INDEX('Pliegos Tarifarios (Quilicura)'!$E:$E,MATCH($B7,'Pliegos Tarifarios (Quilicura)'!$A:$A,0)) -> 54864.994 | Q7: {=H7*_xlfn.IFS(H7<=350,INDEX('Pliegos Tarifarios (Quilicura)'!$F:$F,MATCH($B7,'Pliegos Tarifarios (Quilicura)'!$A:$A,0)),H7<=500,INDEX('Pliegos Tarifarios (Quilicura)'!$G:$G,MATCH($B7,'Pliegos Tarifarios (Quilicura)'!$A:$A,0)),H7<=1000,INDEX('Pliegos Tarifarios (Quilicura)'!$H:$H,MATCH($B7,'Pliegos Tarifarios (Quilicura)'!$A:$A,0)),H7<=5000,INDEX('Pliegos Tarifarios (Quilicura)'!$I:$I,MATCH($B7,'Pliegos Tarifarios (Quilicura)'!$A:$A,0)),H7>5000,INDEX('Pliegos Tarifarios (Quilicura)'!$J:$J,MATCH($B7,'Pliegos Tarifarios (Quilicura)'!$A:$A,0)))/1.19} -> 12731.293 | R7: =INDEX('Pliegos Tarifarios (Quilicura)'!$K:$K,MATCH($B7,'Pliegos Tarifarios (Quilicura)'!$A:$A,0)) -> 710.782 | S7: =SUM(M7:R7) -> 766694.99 | T7: =S7*0.19 -> 145672.05 | U7: 0 | V7: =SUM(S7:T7) -> 912367.04
A8: Enero | B8: 1 | C8: Arauco Premium Outlet Buenaventura | D8: OT-005 | E8: Retail | F8: Paris | G8: 3P | H8: 4582.2554 | I8: 12.5481 | J8: 11.9749 | K8: 0.95431978 | L8: 147.81 | M8: =H8*INDEX('Pliegos Tarifarios (Quilicura)'!$B:$B,MATCH($B8,'Pliegos Tarifarios (Quilicura)'!$A:$A,0)) -> 544546.07 | N8: =I8*INDEX('Pliegos Tarifarios (Quilicura)'!$C:$C,MATCH($B8,'Pliegos Tarifarios (Quilicura)'!$A:$A,0)) -> 42853.129 | O8: =J8*INDEX('Pliegos Tarifarios (Quilicura)'!$D:$D,MATCH($B8,'Pliegos Tarifarios (Quilicura)'!$A:$A,0)) -> 168925.18 | P8: =H8*INDEX('Pliegos Tarifarios (Quilicura)'!$E:$E,MATCH($B8,'Pliegos Tarifarios (Quilicura)'!$A:$A,0)) -> 59257.727 | Q8: {=H8*_xlfn.IFS(H8<=350,INDEX('Pliegos Tarifarios (Quilicura)'!$F:$F,MATCH($B8,'Pliegos Tarifarios (Quilicura)'!$A:$A,0)),H8<=500,INDEX('Pliegos Tarifarios (Quilicura)'!$G:$G,MATCH($B8,'Pliegos Tarifarios (Quilicura)'!$A:$A,0)),H8<=1000,INDEX('Pliegos Tarifarios (Quilicura)'!$H:$H,MATCH($B8,'Pliegos Tarifarios (Quilicura)'!$A:$A,0)),H8<=5000,INDEX('Pliegos Tarifarios (Quilicura)'!$I:$I,MATCH($B8,'Pliegos Tarifarios (Quilicura)'!$A:$A,0)),H8>5000,INDEX('Pliegos Tarifarios (Quilicura)'!$J:$J,MATCH($B8,'Pliegos Tarifarios (Quilicura)'!$A:$A,0)))/1.19} -> 13750.617 | R8: =INDEX('Pliegos Tarifarios (Quilicura)'!$K:$K,MATCH($B8,'Pliegos Tarifarios (Quilicura)'!$A:$A,0)) -> 710.782 | S8: =SUM(M8:R8) -> 830043.51 | T8: =S8*0.19 -> 157708.27 | U8: 0 | V8: =SUM(S8:T8) -> 987751.77
A9: Enero | B9: 1 | C9: Arauco Premium Outlet Buenaventura | D9: OT-006 | E9: Retail | F9: La Polar | G9: 3P | H9: 3049.8305 | I9: 7.9974 | J9: 7.9974 | K9: 1 | L9: 98.38 | M9: =H9*INDEX('Pliegos Tarifarios (Quilicura)'!$B:$B,MATCH($B9,'Pliegos Tarifarios (Quilicura)'!$A:$A,0)) -> 362435.76 | N9: =I9*INDEX('Pliegos Tarifarios (Quilicura)'!$C:$C,MATCH($B9,'Pliegos Tarifarios (Quilicura)'!$A:$A,0)) -> 27311.993 | O9: =J9*INDEX('Pliegos Tarifarios (Quilicura)'!$D:$D,MATCH($B9,'Pliegos Tarifarios (Quilicura)'!$A:$A,0)) -> 112816.16 | P9: =H9*INDEX('Pliegos Tarifarios (Quilicura)'!$E:$E,MATCH($B9,'Pliegos Tarifarios (Quilicura)'!$A:$A,0)) -> 39440.408 | Q9: {=H9*_xlfn.IFS(H9<=350,INDEX('Pliegos Tarifarios (Quilicura)'!$F:$F,MATCH($B9,'Pliegos Tarifarios (Quilicura)'!$A:$A,0)),H9<=500,INDEX('Pliegos Tarifarios (Quilicura)'!$G:$G,MATCH($B9,'Pliegos Tarifarios (Quilicura)'!$A:$A,0)),H9<=1000,INDEX('Pliegos Tarifarios (Quilicura)'!$H:$H,MATCH($B9,'Pliegos Tarifarios (Quilicura)'!$A:$A,0)),H9<=5000,INDEX('Pliegos Tarifarios (Quilicura)'!$I:$I,MATCH($B9,'Pliegos Tarifarios (Quilicura)'!$A:$A,0)),H9>5000,INDEX('Pliegos Tarifarios (Quilicura)'!$J:$J,MATCH($B9,'Pliegos Tarifarios (Quilicura)'!$A:$A,0)))/1.19} -> 9152.0544 | R9: =INDEX('Pliegos Tarifarios (Quilicura)'!$K:$K,MATCH($B9,'Pliegos Tarifarios (Quilicura)'!$A:$A,0)) -> 710.782 | S9: =SUM(M9:R9) -> 551867.16 | T9: =S9*0.19 -> 104854.76 | U9: 0 | V9: =SUM(S9:T9) -> 656721.92
A10: Enero | B10: 1 | C10: Arauco Premium Outlet Buenaventura | D10: OT-007 | E10: Retail | F10: Tricot | G10: 1P | H10: 1020.5297 | I10: 2.7045 | J10: 2.6648 | K10: 0.98532076 | L10: 32.92 | M10: =H10*INDEX('Pliegos Tarifarios (Quilicura)'!$B:$B,MATCH($B10,'Pliegos Tarifarios (Quilicura)'!$A:$A,0)) -> 121277.71 | N10: =I10*INDEX('Pliegos Tarifarios (Quilicura)'!$C:$C,MATCH($B10,'Pliegos Tarifarios (Quilicura)'!$A:$A,0)) -> 9236.1623 | O10: =J10*INDEX('Pliegos Tarifarios (Quilicura)'!$D:$D,MATCH($B10,'Pliegos Tarifarios (Quilicura)'!$A:$A,0)) -> 37591.281 | P10: =H10*INDEX('Pliegos Tarifarios (Quilicura)'!$E:$E,MATCH($B10,'Pliegos Tarifarios (Quilicura)'!$A:$A,0)) -> 13197.49 | Q10: {=H10*_xlfn.IFS(H10<=350,INDEX('Pliegos Tarifarios (Quilicura)'!$F:$F,MATCH($B10,'Pliegos Tarifarios (Quilicura)'!$A:$A,0)),H10<=500,INDEX('Pliegos Tarifarios (Quilicura)'!$G:$G,MATCH($B10,'Pliegos Tarifarios (Quilicura)'!$A:$A,0)),H10<=1000,INDEX('Pliegos Tarifarios (Quilicura)'!$H:$H,MATCH($B10,'Pliegos Tarifarios (Quilicura)'!$A:$A,0)),H10<=5000,INDEX('Pliegos Tarifarios (Quilicura)'!$I:$I,MATCH($B10,'Pliegos Tarifarios (Quilicura)'!$A:$A,0)),H10>5000,INDEX('Pliegos Tarifarios (Quilicura)'!$J:$J,MATCH($B10,'Pliegos Tarifarios (Quilicura)'!$A:$A,0)))/1.19} -> 3062.4467 | R10: =INDEX('Pliegos Tarifarios (Quilicura)'!$K:$K,MATCH($B10,'Pliegos Tarifarios (Quilicura)'!$A:$A,0)) -> 710.782 | S10: =SUM(M10:R10) -> 185075.87 | T10: =S10*0.19 -> 35164.415 | U10: 0 | V10: =SUM(S10:T10) -> 220240.29
A11: Enero | B11: 1 | C11: Arauco Premium Outlet Buenaventura | D11: OT-008 | E11: Retail | F11: Easy | G11: 3P | H11: 3054.2882 | I11: 8.2843 | J11: 8.0113 | K11: 0.9670461 | L11: 98.53 | M11: =H11*INDEX('Pliegos Tarifarios (Quilicura)'!$B:$B,MATCH($B11,'Pliegos Tarifarios (Quilicura)'!$A:$A,0)) -> 362965.5 | N11: =I11*INDEX('Pliegos Tarifarios (Quilicura)'!$C:$C,MATCH($B11,'Pliegos Tarifarios (Quilicura)'!$A:$A,0)) -> 28291.787 | O11: =J11*INDEX('Pliegos Tarifarios (Quilicura)'!$D:$D,MATCH($B11,'Pliegos Tarifarios (Quilicura)'!$A:$A,0)) -> 113012.24 | P11: =H11*INDEX('Pliegos Tarifarios (Quilicura)'!$E:$E,MATCH($B11,'Pliegos Tarifarios (Quilicura)'!$A:$A,0)) -> 39498.055 | Q11: {=H11*_xlfn.IFS(H11<=350,INDEX('Pliegos Tarifarios (Quilicura)'!$F:$F,MATCH($B11,'Pliegos Tarifarios (Quilicura)'!$A:$A,0)),H11<=500,INDEX('Pliegos Tarifarios (Quilicura)'!$G:$G,MATCH($B11,'Pliegos Tarifarios (Quilicura)'!$A:$A,0)),H11<=1000,INDEX('Pliegos Tarifarios (Quilicura)'!$H:$H,MATCH($B11,'Pliegos Tarifarios (Quilicura)'!$A:$A,0)),H11<=5000,INDEX('Pliegos Tarifarios (Quilicura)'!$I:$I,MATCH($B11,'Pliegos Tarifarios (Quilicura)'!$A:$A,0)),H11>5000,INDEX('Pliegos Tarifarios (Quilicura)'!$J:$J,MATCH($B11,'Pliegos Tarifarios (Quilicura)'!$A:$A,0)))/1.19} -> 9165.4312 | R11: =INDEX('Pliegos Tarifarios (Quilicura)'!$K:$K,MATCH($B11,'Pliegos Tarifarios (Quilicura)'!$A:$A,0)) -> 710.782 | S11: =SUM(M11:R11) -> 553643.8 | T11: =S11*0.19 -> 105192.32 | U11: 0 | V11: =SUM(S11:T11) -> 658836.12
A12: Enero | B12: 1 | C12: Arauco Premium Outlet Buenaventura | D12: OT-009 | E12: Ropa | F12: H&M | G12: 1P | H12: 1271.0168 | I12: 3.3972 | J12: 3.3339 | K12: 0.98136701 | L12: 41 | M12: =H12*INDEX('Pliegos Tarifarios (Quilicura)'!$B:$B,MATCH($B12,'Pliegos Tarifarios (Quilicura)'!$A:$A,0)) -> 151045.09 | N12: =I12*INDEX('Pliegos Tarifarios (Quilicura)'!$C:$C,MATCH($B12,'Pliegos Tarifarios (Quilicura)'!$A:$A,0)) -> 11601.808 | O12: =J12*INDEX('Pliegos Tarifarios (Quilicura)'!$D:$D,MATCH($B12,'Pliegos Tarifarios (Quilicura)'!$A:$A,0)) -> 47030.01 | P12: =H12*INDEX('Pliegos Tarifarios (Quilicura)'!$E:$E,MATCH($B12,'Pliegos Tarifarios (Quilicura)'!$A:$A,0)) -> 16436.789 | Q12: {=H12*_xlfn.IFS(H12<=350,INDEX('Pliegos Tarifarios (Quilicura)'!$F:$F,MATCH($B12,'Pliegos Tarifarios (Quilicura)'!$A:$A,0)),H12<=500,INDEX('Pliegos Tarifarios (Quilicura)'!$G:$G,MATCH($B12,'Pliegos Tarifarios (Quilicura)'!$A:$A,0)),H12<=1000,INDEX('Pliegos Tarifarios (Quilicura)'!$H:$H,MATCH($B12,'Pliegos Tarifarios (Quilicura)'!$A:$A,0)),H12<=5000,INDEX('Pliegos Tarifarios (Quilicura)'!$I:$I,MATCH($B12,'Pliegos Tarifarios (Quilicura)'!$A:$A,0)),H12>5000,INDEX('Pliegos Tarifarios (Quilicura)'!$J:$J,MATCH($B12,'Pliegos Tarifarios (Quilicura)'!$A:$A,0)))/1.19} -> 3814.1185 | R12: =INDEX('Pliegos Tarifarios (Quilicura)'!$K:$K,MATCH($B12,'Pliegos Tarifarios (Quilicura)'!$A:$A,0)) -> 710.782 | S12: =SUM(M12:R12) -> 230638.6 | T12: =S12*0.19 -> 43821.335 | U12: 0 | V12: =SUM(S12:T12) -> 274459.94
A13: Enero | B13: 1 | C13: Arauco Premium Outlet Buenaventura | D13: OT-010 | E13: Ropa | F13: Adidas | G13: 1P | H13: 1016.7444 | I13: 2.7021 | J13: 2.6641 | K13: 0.98593686 | L13: 32.8 | M13: =H13*INDEX('Pliegos Tarifarios (Quilicura)'!$B:$B,MATCH($B13,'Pliegos Tarifarios (Quilicura)'!$A:$A,0)) -> 120827.87 | N13: =I13*INDEX('Pliegos Tarifarios (Quilicura)'!$C:$C,MATCH($B13,'Pliegos Tarifarios (Quilicura)'!$A:$A,0)) -> 9227.966 | O13: =J13*INDEX('Pliegos Tarifarios (Quilicura)'!$D:$D,MATCH($B13,'Pliegos Tarifarios (Quilicura)'!$A:$A,0)) -> 37581.406 | P13: =H13*INDEX('Pliegos Tarifarios (Quilicura)'!$E:$E,MATCH($B13,'Pliegos Tarifarios (Quilicura)'!$A:$A,0)) -> 13148.539 | Q13: {=H13*_xlfn.IFS(H13<=350,INDEX('Pliegos Tarifarios (Quilicura)'!$F:$F,MATCH($B13,'Pliegos Tarifarios (Quilicura)'!$A:$A,0)),H13<=500,INDEX('Pliegos Tarifarios (Quilicura)'!$G:$G,MATCH($B13,'Pliegos Tarifarios (Quilicura)'!$A:$A,0)),H13<=1000,INDEX('Pliegos Tarifarios (Quilicura)'!$H:$H,MATCH($B13,'Pliegos Tarifarios (Quilicura)'!$A:$A,0)),H13<=5000,INDEX('Pliegos Tarifarios (Quilicura)'!$I:$I,MATCH($B13,'Pliegos Tarifarios (Quilicura)'!$A:$A,0)),H13>5000,INDEX('Pliegos Tarifarios (Quilicura)'!$J:$J,MATCH($B13,'Pliegos Tarifarios (Quilicura)'!$A:$A,0)))/1.19} -> 3051.0876 | R13: =INDEX('Pliegos Tarifarios (Quilicura)'!$K:$K,MATCH($B13,'Pliegos Tarifarios (Quilicura)'!$A:$A,0)) -> 710.782 | S13: =SUM(M13:R13) -> 184547.65 | T13: =S13*0.19 -> 35064.054 | U13: 0 | V13: =SUM(S13:T13) -> 219611.71
A14: Enero | B14: 1 | C14: Arauco Premium Outlet Buenaventura | D14: OT-011 | E14: Ropa | F14: Nike | G14: 1P | H14: 1016.8202 | I14: 2.6934 | J14: 2.6674 | K14: 0.99034677 | L14: 32.8 | M14: =H14*INDEX('Pliegos Tarifarios (Quilicura)'!$B:$B,MATCH($B14,'Pliegos Tarifarios (Quilicura)'!$A:$A,0)) -> 120836.88 | N14: =I14*INDEX('Pliegos Tarifarios (Quilicura)'!$C:$C,MATCH($B14,'Pliegos Tarifarios (Quilicura)'!$A:$A,0)) -> 9198.2546 | O14: =J14*INDEX('Pliegos Tarifarios (Quilicura)'!$D:$D,MATCH($B14,'Pliegos Tarifarios (Quilicura)'!$A:$A,0)) -> 37627.958 | P14: =H14*INDEX('Pliegos Tarifarios (Quilicura)'!$E:$E,MATCH($B14,'Pliegos Tarifarios (Quilicura)'!$A:$A,0)) -> 13149.519 | Q14: {=H14*_xlfn.IFS(H14<=350,INDEX('Pliegos Tarifarios (Quilicura)'!$F:$F,MATCH($B14,'Pliegos Tarifarios (Quilicura)'!$A:$A,0)),H14<=500,INDEX('Pliegos Tarifarios (Quilicura)'!$G:$G,MATCH($B14,'Pliegos Tarifarios (Quilicura)'!$A:$A,0)),H14<=1000,INDEX('Pliegos Tarifarios (Quilicura)'!$H:$H,MATCH($B14,'Pliegos Tarifarios (Quilicura)'!$A:$A,0)),H14<=5000,INDEX('Pliegos Tarifarios (Quilicura)'!$I:$I,MATCH($B14,'Pliegos Tarifarios (Quilicura)'!$A:$A,0)),H14>5000,INDEX('Pliegos Tarifarios (Quilicura)'!$J:$J,MATCH($B14,'Pliegos Tarifarios (Quilicura)'!$A:$A,0)))/1.19} -> 3051.3151 | R14: =INDEX('Pliegos Tarifarios (Quilicura)'!$K:$K,MATCH($B14,'Pliegos Tarifarios (Quilicura)'!$A:$A,0)) -> 710.782 | S14: =SUM(M14:R14) -> 184574.71 | T14: =S14*0.19 -> 35069.194 | U14: 0 | V14: =SUM(S14:T14) -> 219643.9
A15: Enero | B15: 1 | C15: Arauco Premium Outlet Buenaventura | D15: OT-012 | E15: Ropa | F15: Puma | G15: 1P | H15: 764.1477 | I15: 2.0596 | J15: 1.9894 | K15: 0.96591571 | L15: 24.65 | M15: =H15*INDEX('Pliegos Tarifarios (Quilicura)'!$B:$B,MATCH($B15,'Pliegos Tarifarios (Quilicura)'!$A:$A,0)) -> 90809.784 | N15: =I15*INDEX('Pliegos Tarifarios (Quilicura)'!$C:$C,MATCH($B15,'Pliegos Tarifarios (Quilicura)'!$A:$A,0)) -> 7033.7585 | O15: =J15*INDEX('Pliegos Tarifarios (Quilicura)'!$D:$D,MATCH($B15,'Pliegos Tarifarios (Quilicura)'!$A:$A,0)) -> 28063.68 | P15: =H15*INDEX('Pliegos Tarifarios (Quilicura)'!$E:$E,MATCH($B15,'Pliegos Tarifarios (Quilicura)'!$A:$A,0)) -> 9881.9581 | Q15: {=H15*_xlfn.IFS(H15<=350,INDEX('Pliegos Tarifarios (Quilicura)'!$F:$F,MATCH($B15,'Pliegos Tarifarios (Quilicura)'!$A:$A,0)),H15<=500,INDEX('Pliegos Tarifarios (Quilicura)'!$G:$G,MATCH($B15,'Pliegos Tarifarios (Quilicura)'!$A:$A,0)),H15<=1000,INDEX('Pliegos Tarifarios (Quilicura)'!$H:$H,MATCH($B15,'Pliegos Tarifarios (Quilicura)'!$A:$A,0)),H15<=5000,INDEX('Pliegos Tarifarios (Quilicura)'!$I:$I,MATCH($B15,'Pliegos Tarifarios (Quilicura)'!$A:$A,0)),H15>5000,INDEX('Pliegos Tarifarios (Quilicura)'!$J:$J,MATCH($B15,'Pliegos Tarifarios (Quilicura)'!$A:$A,0)))/1.19} -> 1792.2153 | R15: =INDEX('Pliegos Tarifarios (Quilicura)'!$K:$K,MATCH($B15,'Pliegos Tarifarios (Quilicura)'!$A:$A,0)) -> 710.782 | S15: =SUM(M15:R15) -> 138292.18 | T15: =S15*0.19 -> 26275.514 | U15: 0 | V15: =SUM(S15:T15) -> 164567.69
... A843: Diciembre | B843: 12 | C843: Arauco Premium Outlet Buenaventura | D843: OT-070 | E843: Local no sensado | F843: Local no sensado 27 | G843: 3P | H843: 2335.0824 | I843: 6.165 | J843: 6.1345 | K843: 0.99505272 | L843: 75.33 | M843: =H843*INDEX('Pliegos Tarifarios (Quilicura)'!$B:$B,MATCH($B843,'Pliegos Tarifarios (Quilicura)'!$A:$A,0)) -> 307677.46 | N843: =I843*INDEX('Pliegos Tarifarios (Quilicura)'!$C:$C,MATCH($B843,'Pliegos Tarifarios (Quilicura)'!$A:$A,0)) -> 21361.62 | O843: =J843*INDEX('Pliegos Tarifarios (Quilicura)'!$D:$D,MATCH($B843,'Pliegos Tarifarios (Quilicura)'!$A:$A,0)) -> 89188.569 | P843: =H843*INDEX('Pliegos Tarifarios (Quilicura)'!$E:$E,MATCH($B843,'Pliegos Tarifarios (Quilicura)'!$A:$A,0)) -> 30412.113 | Q843: {=H843*_xlfn.IFS(H843<=350,INDEX('Pliegos Tarifarios (Quilicura)'!$F:$F,MATCH($B843,'Pliegos Tarifarios (Quilicura)'!$A:$A,0)),H843<=500,INDEX('Pliegos Tarifarios (Quilicura)'!$G:$G,MATCH($B843,'Pliegos Tarifarios (Quilicura)'!$A:$A,0)),H843<=1000,INDEX('Pliegos Tarifarios (Quilicura)'!$H:$H,MATCH($B843,'Pliegos Tarifarios (Quilicura)'!$A:$A,0)),H843<=5000,INDEX('Pliegos Tarifarios (Quilicura)'!$I:$I,MATCH($B843,'Pliegos Tarifarios (Quilicura)'!$A:$A,0)),H843>5000,INDEX('Pliegos Tarifarios (Quilicura)'!$J:$J,MATCH($B843,'Pliegos Tarifarios (Quilicura)'!$A:$A,0)))/1.19} -> 7146.5295 | R843: =INDEX('Pliegos Tarifarios (Quilicura)'!$K:$K,MATCH($B843,'Pliegos Tarifarios (Quilicura)'!$A:$A,0)) -> 733.353 | S843: =SUM(M843:R843) -> 456519.65 | T843: =S843*0.19 -> 86738.733 | U843: 0 | V843: =SUM(S843:T843) -> 543258.38

Sheet Pliegos Tarifarios (Quilicura)
A1: Mes | B1: Consumo Energía (kWh) | C1: Dda. Máx. Suministrada(kW) | D1: Dda. Máx. Hora Punta(kW) | E1: KWH para Sistema Troncal | F1: KWH para Serv. Público IVA 1 | G1: KWH para Serv. Público IVA 2 | H1: KWH para Serv. Público IVA 3 | I1: KWH para Serv. Público IVA 4 | J1: KWH para Serv. Público IVA 5 | K1: Cargo Fijo ($)
A2: 1 | B2: 118.838 | C2: 3415.109 | D2: 14106.605 | E2: 12.932 | F2: 0.784 | G2: =$F2+0.892 -> 1.676 | H2: =$F2+2.007 -> 2.791 | I2: =$F2+2.787 -> 3.571 | J2: =$F2+ 3.121 -> 3.905 | K2: 710.782
A3: 2 | B3: 118.838 | C3: 3430.681 | D3: 14122.176 | E3: 12.932 | F3: 0.784 | G3: =$F3+0.892 -> 1.676 | H3: =$F3+2.007 -> 2.791 | I3: =$F3+2.787 -> 3.571 | J3: =$F3+ 3.121 -> 3.905 | K3: 709.361
A4: 3 | B4: 118.838 | C4: 3492.269 | D4: 14192.815 | E4: 12.932 | F4: 0.784 | G4: =$F4+0.892 -> 1.676 | H4: =$F4+2.007 -> 2.791 | I4: =$F4+2.787 -> 3.571 | J4: =$F4+ 3.121 -> 3.905 | K4: 716.899
A5: 4 | B5: 118.838 | C5: 3429.857 | D5: 14128.42 | E5: 12.932 | F5: 0.784 | G5: =$F5+0.892 -> 1.676 | H5: =$F5+2.007 -> 2.791 | I5: =$F5+2.787 -> 3.571 | J5: =$F5+ 3.121 -> 3.905 | K5: 719.689
A6: 5 | B6: 118.838 | C6: 3400.471 | D6: 14099.714 | E6: 12.932 | F6: 0.784 | G6: =$F6+0.892 -> 1.676 | H6: =$F6+2.007 -> 2.791 | I6: =$F6+2.787 -> 3.571 | J6: =$F6+ 3.121 -> 3.905 | K6: 723.328
A7: 6 | B7: 118.838 | C7: 3460.555 | D7: 14164.529 | E7: 12.932 | F7: 0.784 | G7: =$F7+0.892 -> 1.676 | H7: =$F7+2.007 -> 2.791 | I7: =$F7+2.787 -> 3.571 | J7: =$F7+ 3.121 -> 3.905 | K7: 724.748
A8: 7 | B8: 131.763 | C8: 3407.639 | D8: 14473 | E8: 13.024 | F8: 0.784 | G8: =$F8+0.892 -> 1.676 | H8: =$F8+2.007 -> 2.791 | I8: =$F8+2.787 -> 3.571 | J8: =$F8+ 3.121 -> 3.905 | K8: 726.16
A9: 8 | B9: 131.763 | C9: 3400.773 | D9: 14463.655 | E9: 13.024 | F9: 0.784 | G9: =$F9+0.892 -> 1.676 | H9: =$F9+2.007 -> 2.791 | I9: =$F9+2.787 -> 3.571 | J9: =$F9+ 3.121 -> 3.905 | K9: 723.176
A10: 9 | B10: 131.763 | C10: 3442.319 | D10: 14512.134 | E10: 13.024 | F10: 0.784 | G10: =$F10+0.892 -> 1.676 | H10: =$F10+2.007 -> 2.791 | I10: =$F10+2.787 -> 3.571 | J10: =$F10+ 3.121 -> 3.905 | K10: 729.504
A11: 10 | B11: 131.763 | C11: 3473.664 | D11: 14545.605 | E11: 13.024 | F11: 0.784 | G11: =$F11+0.892 -> 1.676 | H11: =$F11+2.007 -> 2.791 | I11: =$F11+2.787 -> 3.571 | J11: =$F11+ 3.121 -> 3.905 | K11: 729.756
A12: 11 | B12: 131.763 | C12: 3475.403 | D12: 14549.672 | E12: 13.024 | F12: 0.784 | G12: =$F12+0.892 -> 1.676 | H12: =$F12+2.007 -> 2.791 | I12: =$F12+2.787 -> 3.571 | J12: =$F12+ 3.121 -> 3.905 | K12: 732.992
A13: 12 | B13: 131.763 | C13: 3464.983 | D13: 14538.849 | E13: 13.024 | F13: 0.855 | G13: =$F13+0.892 -> 1.747 | H13: =$F13+2.007 -> 2.862 | I13: =$F13+2.787 -> 3.642 | J13: =$F13+ 3.121 -> 3.976 | K13: 733.353

Sheet Consumo por Local (Pivot)
A1: POWER Digital® — Arauco Express El Carmen de Huechuraba — Resumen Anual por Local 2025
A3: ① CONSUMO MENSUAL POR LOCAL (kWh)
A4: ID Medidor | B4: Nombre Local | C4: Enero | D4: Febrero | E4: Marzo | F4: Abril | G4: Mayo | H4: Junio | I4: Julio | J4: Agosto | K4: Septiembre | L4: Octubre | M4: Noviembre | N4: Diciembre | O4: TOTAL ANUAL
A5: SC53-001 | B5: Servicios comunes | C5: 8017.1631 | D5: 6465.9756 | E5: 7352.4826 | F5: 6277.2563 | G5: 7289.6094 | H5: 6707.2506 | I5: 7142.5403 | J5: 7117.8569 | K5: 6629.5118 | L5: 8014.5571 | M5: 7969.7657 | N5: 9741.2538 | O5: 88725.223
A6: SC53-002 | B6: Supermercado | C6: 4015.0057 | D6: 3236.0593 | E6: 3669.6461 | F6: 3144.1786 | G6: 3643.4116 | H6: 3344.7624 | I6: 3557.3129 | J6: 3556.3344 | K6: 3304.8405 | L6: 4002.8296 | M6: 3981.2266 | N6: 4861.7174 | O6: 44317.325
A7: SC53-003 | B7: supermercado2 | C7: 3215.0359 | D7: 2581.9852 | E7: 2934.9503 | F7: 2510.0906 | G7: 2910.1338 | H7: 2668.2641 | I7: 2848.8535 | J7: 2850.3975 | K7: 2643.8837 | L7: 3198.3334 | M7: 3187.6497 | N7: 3894.9017 | O7: 35444.479
A8: SC53-004 | B8: Ripley | C8: 2672.1547 | D8: 2156.4426 | E8: 2445.9214 | F8: 2098.8313 | G8: 2431.0028 | H8: 2230.5901 | I8: 2376.3532 | J8: 2373.7979 | K8: 2204.9623 | L8: 2673.6725 | M8: 2652.2976 | N8: 3242.3162 | O8: 29558.343
A9: SC53-005 | B9: Paris | C9: 2889.9791 | D9: 2328.1445 | E9: 2644.0256 | F9: 2267.5833 | G9: 2631.8265 | H9: 2409.9666 | I9: 2559.6615 | J9: 2560.4535 | K9: 2382.2563 | L9: 2882.5866 | M9: 2862.5131 | N9: 3504.7654 | O9: 31923.762
A10: SC53-006 | B10: La Polar | C10: 1922.7836 | D10: 1553.1373 | E10: 1762.4069 | F10: 1507.154 | G10: 1753.6942 | H10: 1603.5962 | I10: 1706.7898 | J10: 1704.0758 | K10: 1586.4188 | L10: 1913.862 | M10: 1915.703 | N10: 2338.3079 | O10: 21267.929
A11: SC53-007 | B11: Tricot | C11: 641.8899 | D11: 518.8858 | E11: 585.9127 | F11: 503.3323 | G11: 583.806 | H11: 535.4818 | I11: 569.5178 | J11: 569.2884 | K11: 528.7138 | L11: 641.5728 | M11: 637.3431 | N11: 779.9076 | O11: 7095.652
A12: SC53-008 | B12: Easy | C12: 1931.0001 | D12: 1554.639 | E12: 1766.2565 | F12: 1510.1639 | G12: 1752.6916 | H12: 1608.5459 | I12: 1705.3075 | J12: 1707.1816 | K12: 1586.5017 | L12: 1919.5386 | M12: 1909.8042 | N12: 2341.0062 | O12: 21292.637
A13: SC53-009 | B13: H&M | C13: 801.9504 | D13: 646.8447 | E13: 735.583 | F13: 629.1243 | G13: 727.3767 | H13: 669.25 | I13: 710.0877 | J13: 711.1066 | K13: 659.8917 | L13: 800.9062 | M13: 796.6959 | N13: 975.1473 | O13: 8863.9645
A14: SC53-010 | B14: Adidas | C14: 642.9813 | D14: 516.6836 | E14: 586.7425 | F14: 503.7891 | G14: 582.6232 | H14: 535.1927 | I14: 568.1354 | J14: 568.6998 | K14: 528.4306 | L14: 639.9261 | M14: 636.896 | N14: 780.2195 | O14: 7090.3198
A15: SC53-011 | B15: Nike | C15: 1283.4444 | D15: 1033.9082 | E15: 1173.8728 | F15: 1008.5674 | G15: 1168.0826 | H15: 1071.2231 | I15: 1139.5179 | J15: 1137.2723 | K15: 1056.304 | L15: 1281.1481 | M15: 1275.2282 | N15: 1557.9812 | O15: 14186.55
A16: SC53-012 | B16: Puma | C16: 483.1684 | D16: 388.5696 | E16: 439.8898 | F16: 376.6556 | G16: 437.9411 | H16: 401.362 | I16: 426.7736 | J16: 427.3881 | K16: 396.9805 | L16: 481.2525 | M16: 478.041 | N16: 584.2185 | O16: 5322.2407
... A58: TOTAL CENTRO | B58: Todos los locales | C58: 53519.473 | D58: 43105.209 | E58: 48964.771 | F58: 41931.582 | G58: 48603.364 | H58: 44620.381 | I58: 47447.723 | J58: 47439.26 | K58: 44082.805 | L58: 53390.56 | M58: 53105.214 | N58: 64940.949 | O58: 591151.29
A60: ② PEAK MENSUAL POR LOCAL (kW)
A61: ID Medidor | B61: Nombre Local | C61: Enero | D61: Febrero | E61: Marzo | F61: Abril | G61: Mayo | H61: Junio | I61: Julio | J61: Agosto | K61: Septiembre | L61: Octubre | M61: Noviembre | N61: Diciembre | O61: TOTAL ANUAL
A62: SC53-001 | B62: Servicios comunes | C62: 21.1058 | D62: 19.5231 | E62: 19.6501 | F62: 17.8659 | G62: 20.4987 | H62: 18.6494 | I62: 18.9654 | J62: 19.1854 | K62: 18.708 | L62: 21.3069 | M62: 21.9115 | N62: 25.6674 | O62: 25.6674
A63: SC53-002 | B63: Supermercado | C63: 10.6918 | D63: 9.5942 | E63: 9.7746 | F63: 8.856 | G63: 9.6662 | H63: 9.3636 | I63: 9.6601 | J63: 9.669 | K63: 9.3696 | L63: 10.6927 | M63: 11.1501 | N63: 12.6865 | O63: 12.6865
A64: SC53-003 | B64: supermercado2 | C64: 8.6385 | D64: 7.8562 | E64: 7.8753 | F64: 7.0696 | G64: 7.9132 | H64: 7.6387 | I64: 7.5271 | J64: 7.7588 | K64: 7.4216 | L64: 8.5965 | M64: 8.8093 | N64: 10.1057 | O64: 10.1057
A65: SC53-004 | B65: Ripley | C65: 7.1231 | D65: 6.57 | E65: 6.5821 | F65: 5.9537 | G65: 6.6493 | H65: 6.1505 | I65: 6.3946 | J65: 6.4122 | K65: 6.1261 | L65: 7.2303 | M65: 7.3166 | N65: 8.516 | O65: 8.516
A66: SC53-005 | B66: Paris | C66: 7.814 | D66: 7.009 | E66: 7.1472 | F66: 6.4102 | G66: 7.0966 | H66: 6.704 | I66: 6.9647 | J66: 6.8748 | K66: 6.5951 | L66: 7.582 | M66: 7.7991 | N66: 9.268 | O66: 9.268
A67: SC53-006 | B67: La Polar | C67: 5.095 | D67: 4.6857 | E67: 4.7245 | F67: 4.1459 | G67: 4.7405 | H67: 4.5894 | I67: 4.5766 | J67: 4.5605 | K67: 4.4405 | L67: 5.1765 | M67: 5.4125 | N67: 6.1382 | O67: 6.1382
A68: SC53-007 | B68: Tricot | C68: 1.7223 | D68: 1.5326 | E68: 1.6011 | F68: 1.4196 | G68: 1.5533 | H68: 1.49 | I68: 1.5522 | J68: 1.5323 | K68: 1.5197 | L68: 1.7138 | M68: 1.7282 | N68: 2.0848 | O68: 2.0848
A69: SC53-008 | B69: Easy | C69: 5.2555 | D69: 4.6946 | E69: 4.6966 | F69: 4.2018 | G69: 4.6796 | H69: 4.5215 | I69: 4.7152 | J69: 4.6121 | K69: 4.4615 | L69: 5.0573 | M69: 5.1936 | N69: 6.1468 | O69: 6.1468
A70: SC53-009 | B70: H&M | C70: 2.1338 | D70: 1.9398 | E70: 1.9637 | F70: 1.8394 | G70: 1.9559 | H70: 1.8756 | I70: 1.9439 | J70: 1.9526 | K70: 1.895 | L70: 2.1213 | M70: 2.2133 | N70: 2.5485 | O70: 2.5485
A71: SC53-010 | B71: Adidas | C71: 1.6821 | D71: 1.5551 | E71: 1.5772 | F71: 1.4039 | G71: 1.6044 | H71: 1.4935 | I71: 1.559 | J71: 1.5384 | K71: 1.5055 | L71: 1.7367 | M71: 1.7531 | N71: 2.125 | O71: 2.125
A72: SC53-011 | B72: Nike | C72: 3.4658 | D72: 3.0639 | E72: 3.1508 | F72: 2.8216 | G72: 3.2318 | H72: 2.9227 | I72: 3.1823 | J72: 3.0049 | K72: 2.9781 | L72: 3.414 | M72: 3.4663 | N72: 4.0781 | O72: 4.0781
A73: SC53-012 | B73: Puma | C73: 1.2697 | D73: 1.1813 | E73: 1.1751 | F73: 1.0567 | G73: 1.1826 | H73: 1.1299 | I73: 1.1955 | J73: 1.1348 | K73: 1.1592 | L73: 1.3059 | M73: 1.3193 | N73: 1.5331 | O73: 1.5331
... A115: TOTAL CENTRO | B115: Todos los locales | C115: 21.1058 | D115: 19.5231 | E115: 19.6501 | F115: 17.8659 | G115: 20.4987 | H115: 18.6494 | I115: 18.9654 | J115: 19.1854 | K115: 18.708 | L115: 21.3069 | M115: 21.9115 | N115: 25.6674 | O115: 25.6674
A117: ③ DEMANDA HORA PUNTA 18:00–22:00 POR LOCAL (kWh)
A118: ID Medidor | B118: Nombre Local | C118: Enero | D118: Febrero | E118: Marzo | F118: Abril | G118: Mayo | H118: Junio | I118: Julio | J118: Agosto | K118: Septiembre | L118: Octubre | M118: Noviembre | N118: Diciembre | O118: TOTAL ANUAL
A119: SC53-001 | B119: Servicios comunes | C119: 1680.4739 | D119: 1353.2784 | E119: 1533.7348 | F119: 1311.026 | G119: 1523.8942 | H119: 1398.1921 | I119: 1492.6449 | J119: 1482.9685 | K119: 1389.7302 | L119: 1678.0635 | M119: 1663.4865 | N119: 2037.0229 | O119: 18544.516
A120: SC53-002 | B120: Supermercado | C120: 836.6329 | D120: 677.3988 | E120: 770.2938 | F120: 655.1221 | G120: 762.842 | H120: 698.6099 | I120: 742.6469 | J120: 740.9054 | K120: 688.6946 | L120: 833.7011 | M120: 832.266 | N120: 1016.2753 | O120: 9255.3888
A121: SC53-003 | B121: supermercado2 | C121: 673.4007 | D121: 537.1896 | E121: 614.4844 | F121: 524.9818 | G121: 607.8793 | H121: 558.2528 | I121: 597.7798 | J121: 595.8036 | K121: 551.1356 | L121: 673.2211 | M121: 667.5144 | N121: 814.6908 | O121: 7416.3339
A122: SC53-004 | B122: Ripley | C122: 558.2003 | D122: 451.1398 | E122: 511.1944 | F122: 436.6683 | G122: 507.2924 | H122: 466.8502 | I122: 496.711 | J122: 495.4665 | K122: 459.0958 | L122: 558.7308 | M122: 553.9775 | N122: 677.3689 | O122: 6172.6959
A123: SC53-005 | B123: Paris | C123: 603.9843 | D123: 486.92 | E123: 552.4348 | F123: 473.3018 | G123: 549.4274 | H123: 502.8275 | I123: 535.3653 | J123: 537.3614 | K123: 495.3829 | L123: 601.1869 | M123: 598.9124 | N123: 730.2155 | O123: 6667.3202
A124: SC53-006 | B124: La Polar | C124: 401.8582 | D124: 326.0228 | E124: 367.4368 | F124: 315.1962 | G124: 364.6653 | H124: 335.6256 | I124: 355.7518 | J124: 354.6722 | K124: 331.3663 | L124: 400.2124 | M124: 399.9834 | N124: 488.3941 | O124: 4441.1851
A125: SC53-007 | B125: Tricot | C125: 134.1764 | D125: 108.5464 | E125: 122.1812 | F125: 105.6238 | G125: 121.853 | H125: 112.2182 | I125: 118.847 | J125: 118.9874 | K125: 110.4984 | L125: 134.2676 | M125: 133.1631 | N125: 162.9214 | O125: 1483.2839
...

Sheet Resumen Ejecutivo
A1: POWER Digital® — Resumen Ejecutivo Mensual — Strip Center 53
A2: Arauco Express El Carmen de Huechuraba | 2025 | 53 medidores
A3: Mes | B3: N° Mes | C3: Consumo Total Centro (kWh) | D3: Peak Máx Centro (kW) | E3: Demanda Punta Total (kWh) | F3: % Punta | G3: Promedio Diario Centro (kWh) | H3: Local con Mayor Consumo
A4: Enero | B4: 1 | C4: 53519.473 | D4: 21.1058 | E4: 11185.773 | F4: 0.2090038 | G4: 1726.4346 | H4: SC53-001 — Servicios comunes
A5: Febrero | B5: 2 | C5: 43105.209 | D5: 19.5231 | E5: 9010.5783 | F5: 0.20903688 | G5: 1539.4718 | H5: SC53-001 — Servicios comunes
A6: Marzo | B6: 3 | C6: 48964.771 | D6: 19.6501 | E6: 10233.174 | F6: 0.20899055 | G6: 1748.7418 | H6: SC53-001 — Servicios comunes
A7: Abril | B7: 4 | C7: 41931.582 | D7: 17.8659 | E7: 8760.3715 | F7: 0.20892061 | G7: 1352.6317 | H7: SC53-001 — Servicios comunes
A8: Mayo | B8: 5 | C8: 48603.364 | D8: 20.4987 | E8: 10154.786 | F8: 0.20893174 | G8: 1620.1121 | H8: SC53-001 — Servicios comunes
A9: Junio | B9: 6 | C9: 44620.381 | D9: 18.6494 | E9: 9321.6055 | F9: 0.20890914 | G9: 1439.3671 | H9: SC53-001 — Servicios comunes
A10: Julio | B10: 7 | C10: 47447.723 | D10: 18.9654 | E10: 9913.2007 | F10: 0.2089289 | G10: 1581.5908 | H10: SC53-001 — Servicios comunes
A11: Agosto | B11: 8 | C11: 47439.26 | D11: 19.1854 | E11: 9905.4316 | F11: 0.20880241 | G11: 1530.2987 | H11: SC53-001 — Servicios comunes
A12: Septiembre | B12: 9 | C12: 44082.805 | D12: 18.708 | E12: 9208.6364 | F12: 0.20889407 | G12: 1422.026 | H12: SC53-001 — Servicios comunes
A13: Octubre | B13: 10 | C13: 53390.56 | D13: 21.3069 | E13: 11160.639 | F13: 0.20903768 | G13: 1779.6853 | H13: SC53-001 — Servicios comunes
A14: Noviembre | B14: 11 | C14: 53105.214 | D14: 21.9115 | E14: 11098.9 | F14: 0.20899831 | G14: 1713.0714 | H14: SC53-001 — Servicios comunes
A15: Diciembre | B15: 12 | C15: 64940.949 | D15: 25.6674 | E15: 13570.184 | F15: 0.20896189 | G15: 2094.8693 | H15: SC53-001 — Servicios comunes
A16: TOTAL ANUAL | C16: 591151.29 | D16: 25.6674 | E16: 123523.28 | F16: 0.20895375
