Workbook

Sheet Resumen
B3: FORMATO DE OFERTA ECONOMICA LICITACIÓN MEDIDORES + EMS CHILE
B5: Resumen Global | C5: Malls | D5: Outlets | E5: StripCenters
B6: CAPEX: NIVEL 1 - EQUIPOS DE MEDICIÓN EN CAMPO | C6: =SUM(D16:D26) -> 0 | D6: =SUM(D27:D30) -> 0 | E6: =SUM(D31:D40) -> 0
B7: CAPEX: NIVEL 2 - SISTEMAS DE CONCENTRACIÓN | C7: =SUM(E16:E26) -> 0 | D7: =SUM(E27:E30) -> 0 | E7: =SUM(E31:E40) -> 0
B8: CAPEX: NIVEL 3 - ARQUITECTURA DE COMUNICACIONES | C8: =SUM(F16:F26) -> 0 | D8: =SUM(F27:F30) -> 0 | E8: =SUM(F31:F40) -> 0
B9: SERVICIOS: INSTALACIÓN, INTEGRACIÓN Y MARCHA | C9: =SUM(G16:G26) -> 0 | D9: =SUM(G27:G30) -> 0 | E9: =SUM(G31:G40) -> 0
B10: OPEX: PLATAFORMA, LICENCIAS | C10: =SUM(H16:H26) -> 0 | D10: =SUM(H27:H30) -> 0 | E10: =SUM(H31:H40) -> 0
B11: OPEX: MANTENCIÓN | C11: =SUM(I16:I26) -> 0 | D11: =SUM(I27:I30) -> 0 | E11: =SUM(I31:I40) -> 0
B12: TOTAL | C12: =SUM(C6:C11) -> 0 | D12: =SUM(D6:D11) -> 0 | E12: =SUM(E6:E11) -> 0
L14: Habilitación de Nuevo Punto | M14: Mantención Nuevo Punto | N14: USO DE SW Nuevo Punto
B15: Centro Comercial | C15: TIPO | D15: Item 1 | E15: Item 2 | F15: Item 3 | G15: Item 4 | H15: Item 5 | I15: Iatem 6 | J15: Total
B16: Parque Arauco Shopping Center | C16: Mall | D16: ='Parque Arauco Shopping Center'!D43 -> 0 | E16: ='Parque Arauco Shopping Center'!D44 -> 0 | F16: ='Parque Arauco Shopping Center'!D45 -> 0 | G16: ='Parque Arauco Shopping Center'!D46 -> 0 | H16: ='Parque Arauco Shopping Center'!D47 -> 0 | I16: ='Parque Arauco Shopping Center'!D48 -> 0 | J16: =SUM(D16:I16) -> 0 | L16: ='Parque Arauco Shopping Center'!D38 -> 0 | M16: ='Parque Arauco Shopping Center'!D39 -> 0 | N16: ='Parque Arauco Shopping Center'!D40 -> 0
B17: Parque Arauco Oriente | C17: Mall | D17: ='Parque Arauco Oriente'!D43 -> 0 | E17: ='Parque Arauco Oriente'!D44 -> 0 | F17: ='Parque Arauco Oriente'!D45 -> 0 | G17: ='Parque Arauco Oriente'!D46 -> 0 | H17: ='Parque Arauco Oriente'!D47 -> 0 | I17: ='Parque Arauco Oriente'!D48 -> 0 | J17: =SUM(D17:I17) -> 0 | L17: ='Parque Arauco Oriente'!D38 -> 0 | M17: ='Parque Arauco Oriente'!D39 -> 0 | N17: ='Parque Arauco Oriente'!D40 -> 0
B18: Arauco Maipú | C18: Mall | D18: ='Arauco Maipú'!D43 -> 0 | E18: ='Arauco Maipú'!D44 -> 0 | F18: ='Arauco Maipú'!D45 -> 0 | G18: ='Arauco Maipú'!D46 -> 0 | H18: ='Arauco Maipú'!D47 -> 0 | I18: ='Arauco Maipú'!D48 -> 0 | J18: =SUM(D18:I18) -> 0 | L18: ='Arauco Maipú'!D38 -> 0 | M18: ='Arauco Maipú'!D39 -> 0 | N18: ='Arauco Maipú'!D40 -> 0
B19: Arauco Estación | C19: Mall | D19: ='Arauco Estación'!D43 -> 0 | E19: ='Arauco Estación'!D44 -> 0 | F19: ='Arauco Estación'!D45 -> 0 | G19: ='Arauco Estación'!D46 -> 0 | H19: ='Arauco Estación'!D47 -> 0 | I19: ='Arauco Estación'!D48 -> 0 | J19: =SUM(D19:I19) -> 0 | L19: ='Arauco Estación'!D38 -> 0 | M19: ='Arauco Estación'!D39 -> 0 | N19: ='Arauco Estación'!D40 -> 0
B20: Arauco San Antonio | C20: Mall | D20: ='Arauco San Antonio'!D43 -> 0 | E20: ='Arauco San Antonio'!D44 -> 0 | F20: ='Arauco San Antonio'!D45 -> 0 | G20: ='Arauco San Antonio'!D46 -> 0 | H20: ='Arauco San Antonio'!D47 -> 0 | I20: ='Arauco San Antonio'!D48 -> 0 | J20: =SUM(D20:I20) -> 0 | L20: ='Arauco San Antonio'!D38 -> 0 | M20: ='Arauco San Antonio'!D39 -> 0 | N20: ='Arauco San Antonio'!D40 -> 0
B21: Arauco Chillán | C21: Mall | D21: ='Arauco Chillán'!D43 -> 0 | E21: ='Arauco Chillán'!D44 -> 0 | F21: ='Arauco Chillán'!D45 -> 0 | G21: ='Arauco Chillán'!D46 -> 0 | H21: ='Arauco Chillán'!D47 -> 0 | I21: ='Arauco Chillán'!D48 -> 0 | J21: =SUM(D21:I21) -> 0 | L21: ='Arauco Chillán'!D38 -> 0 | M21: ='Arauco Chillán'!D39 -> 0 | N21: ='Arauco Chillán'!D40 -> 0
B22: Arauco Coronel | C22: Mall | D22: ='Arauco Coronel'!D43 -> 0 | E22: ='Arauco Coronel'!D44 -> 0 | F22: ='Arauco Coronel'!D45 -> 0 | G22: ='Arauco Coronel'!D46 -> 0 | H22: ='Arauco Coronel'!D47 -> 0 | I22: ='Arauco Coronel'!D48 -> 0 | J22: =SUM(D22:I22) -> 0 | L22: ='Arauco Coronel'!D38 -> 0 | M22: ='Arauco Coronel'!D39 -> 0 | N22: ='Arauco Coronel'!D40 -> 0
B23: Parque Angamos | C23: Mall | D23: ='Parque Angamos'!D43 -> 0 | E23: ='Parque Angamos'!D44 -> 0 | F23: ='Parque Angamos'!D45 -> 0 | G23: ='Parque Angamos'!D46 -> 0 | H23: ='Parque Angamos'!D47 -> 0 | I23: ='Parque Angamos'!D48 -> 0 | J23: =SUM(D23:I23) -> 0 | L23: ='Parque Angamos'!D38 -> 0 | M23: ='Parque Angamos'!D39 -> 0 | N23: ='Parque Angamos'!D40 -> 0
B24: Parque Chicureo | C24: Mall | D24: ='Parque Chicureo'!D43 -> 0 | E24: ='Parque Chicureo'!D44 -> 0 | F24: ='Parque Chicureo'!D45 -> 0 | G24: ='Parque Chicureo'!D46 -> 0 | H24: ='Parque Chicureo'!D47 -> 0 | I24: ='Parque Chicureo'!D48 -> 0 | J24: =SUM(D24:I24) -> 0 | L24: ='Parque Chicureo'!D38 -> 0 | M24: ='Parque Chicureo'!D39 -> 0 | N24: ='Parque Chicureo'!D40 -> 0
B25: Arauco Quilicura | C25: Mall | D25: ='Arauco Quilicura'!D43 -> 0 | E25: ='Arauco Quilicura'!D44 -> 0 | F25: ='Arauco Quilicura'!D45 -> 0 | G25: ='Arauco Quilicura'!D46 -> 0 | H25: ='Arauco Quilicura'!D47 -> 0 | I25: ='Arauco Quilicura'!D48 -> 0 | J25: =SUM(D25:I25) -> 0 | L25: ='Arauco Quilicura'!D38 -> 0 | M25: ='Arauco Quilicura'!D39 -> 0 | N25: ='Arauco Quilicura'!D40 -> 0
B26: Arauco El Bosque | C26: Mall | D26: ='Arauco El Bosque'!D43 -> 0 | E26: ='Arauco El Bosque'!D44 -> 0 | F26: ='Arauco El Bosque'!D45 -> 0 | G26: ='Arauco El Bosque'!D46 -> 0 | H26: ='Arauco El Bosque'!D47 -> 0 | I26: ='Arauco El Bosque'!D48 -> 0 | J26: =SUM(D26:I26) -> 0 | L26: ='Arauco El Bosque'!D38 -> 0 | M26: ='Arauco El Bosque'!D39 -> 0 | N26: ='Arauco El Bosque'!D40 -> 0
B27: Arauco Premium Outlet Buenaventura | C27: Outlet | D27: ='Outlet Buenaventura'!D43 -> 0 | E27: ='Outlet Buenaventura'!D44 -> 0 | F27: ='Outlet Buenaventura'!D45 -> 0 | G27: ='Outlet Buenaventura'!D46 -> 0 | H27: ='Outlet Buenaventura'!D47 -> 0 | I27: ='Outlet Buenaventura'!D48 -> 0 | J27: =SUM(D27:I27) -> 0 | L27: ='Outlet Buenaventura'!D38 -> 0 | M27: ='Outlet Buenaventura'!D39 -> 0 | N27: ='Outlet Buenaventura'!D40 -> 0
B28: Arauco Premium Outlet Curauma | C28: Outlet | D28: =' Outlet Curauma'!D43 -> 0 | E28: =' Outlet Curauma'!D44 -> 0 | F28: =' Outlet Curauma'!D45 -> 0 | G28: =' Outlet Curauma'!D46 -> 0 | H28: =' Outlet Curauma'!D47 -> 0 | I28: =' Outlet Curauma'!D48 -> 0 | J28: =SUM(D28:I28) -> 0 | L28: =' Outlet Curauma'!D38 -> 0 | M28: =' Outlet Curauma'!D39 -> 0 | N28: =' Outlet Curauma'!D40 -> 0
B29: Arauco Premium Outlet Coquimbo | C29: Outlet | D29: ='Outlet Coquimbo'!D43 -> 0 | E29: ='Outlet Coquimbo'!D44 -> 0 | F29: ='Outlet Coquimbo'!F13 -> 0 | G29: ='Outlet Coquimbo'!D46 -> 0 | H29: ='Outlet Coquimbo'!D47 -> 0 | I29: ='Outlet Coquimbo'!D48 -> 0 | J29: =SUM(D29:I29) -> 0 | L29: ='Outlet Coquimbo'!D38 -> 0 | M29: ='Outlet Coquimbo'!D39 -> 0 | N29: ='Outlet Coquimbo'!D40 -> 0
B30: Arauco Premium Outlet San Pedro | C30: Outlet | D30: ='Outlet San Pedro '!D43 -> 0 | E30: ='Outlet San Pedro '!D44 -> 0 | F30: ='Outlet San Pedro '!D45 -> 0 | G30: ='Outlet San Pedro '!D46 -> 0 | H30: ='Outlet San Pedro '!D47 -> 0 | I30: ='Outlet San Pedro '!D48 -> 0 | J30: =SUM(D30:I30) -> 0 | L30: ='Outlet San Pedro '!D38 -> 0 | M30: ='Outlet San Pedro '!D39 -> 0 | N30: ='Outlet San Pedro '!D40 -> 0
B31: Arauco Express Pajaritos | C31: StripCenter | D31: ='AEX Pajaritos'!D43 -> 0 | E31: ='AEX Pajaritos'!D44 -> 0 | F31: ='AEX Pajaritos'!D45 -> 0 | G31: ='AEX Pajaritos'!D46 -> 0 | H31: ='AEX Pajaritos'!D47 -> 0 | I31: ='AEX Pajaritos'!D48 -> 0 | J31: =SUM(D31:I31) -> 0 | L31: ='AEX Pajaritos'!D38 -> 0 | M31: ='AEX Pajaritos'!D39 -> 0 | N31: ='AEX Pajaritos'!D40 -> 0
B32: Arauco Express Ciudad Empresarial | C32: StripCenter | D32: ='AEX CE'!D43 -> 0 | E32: ='AEX CE'!D44 -> 0 | F32: ='AEX CE'!D45 -> 0 | G32: ='AEX CE'!D46 -> 0 | H32: ='AEX CE'!D47 -> 0 | I32: ='AEX CE'!D48 -> 0 | J32: =SUM(D32:I32) -> 0 | L32: ='AEX CE'!D38 -> 0 | M32: ='AEX CE'!D39 -> 0 | N32: ='AEX CE'!D40 -> 0
B33: Arauco Express El Carmen de Huechuraba | C33: StripCenter | D33: ='AEX El Carmen'!D43 -> 0 | E33: ='AEX El Carmen'!D44 -> 0 | F33: ='AEX El Carmen'!D45 -> 0 | G33: ='AEX El Carmen'!D46 -> 0 | H33: ='AEX El Carmen'!D47 -> 0 | I33: ='AEX El Carmen'!D48 -> 0 | J33: =SUM(D33:I33) -> 0 | L33: ='AEX El Carmen'!D38 -> 0 | M33: ='AEX El Carmen'!D39 -> 0 | N33: ='AEX El Carmen'!D40 -> 0
B34: Arauco Express La Reina | C34: StripCenter | D34: ='AEX La Reina'!D43 -> 0 | E34: ='AEX La Reina'!D44 -> 0 | F34: ='AEX La Reina'!D45 -> 0 | G34: ='AEX La Reina'!D46 -> 0 | H34: ='AEX La Reina'!D47 -> 0 | I34: ='AEX La Reina'!D48 -> 0 | J34: =SUM(D34:I34) -> 0 | L34: ='AEX La Reina'!D38 -> 0 | M34: ='AEX La Reina'!D39 -> 0 | N34: ='AEX La Reina'!D40 -> 0
B35: Arauco Express Palmares de Reñaca | C35: StripCenter | D35: ='AEX Reñaca'!D43 -> 0 | E35: ='AEX Reñaca'!D44 -> 0 | F35: ='AEX Reñaca'!D45 -> 0 | G35: ='AEX Reñaca'!D46 -> 0 | H35: ='AEX Reñaca'!D47 -> 0 | I35: ='AEX Reñaca'!D48 -> 0 | J35: =SUM(D35:I35) -> 0 | L35: ='AEX Reñaca'!D38 -> 0 | M35: ='AEX Reñaca'!D39 -> 0 | N35: ='AEX Reñaca'!D40 -> 0
B36: Arauco Express Manuel Montt | C36: StripCenter | D36: ='AEX Manuel Montt'!D43 -> 0 | E36: ='AEX Manuel Montt'!D44 -> 0 | F36: ='AEX Manuel Montt'!D45 -> 0 | G36: ='AEX Manuel Montt'!D46 -> 0 | H36: ='AEX Manuel Montt'!D47 -> 0 | I36: ='AEX Manuel Montt'!D48 -> 0 | J36: =SUM(D36:I36) -> 0 | L36: ='AEX Manuel Montt'!D38 -> 0 | M36: ='AEX Manuel Montt'!D39 -> 0 | N36: ='AEX Manuel Montt'!D40 -> 0
B37: Arauco Express Nueva Calama | C37: StripCenter | D37: ='AEX Calama'!D43 -> 0 | E37: ='AEX Calama'!D44 -> 0 | F37: ='AEX Calama'!D45 -> 0 | G37: ='AEX Calama'!D46 -> 0 | H37: ='AEX Calama'!D47 -> 0 | I37: ='AEX Calama'!D48 -> 0 | J37: =SUM(D37:I37) -> 0 | L37: ='AEX Calama'!D38 -> 0 | M37: ='AEX Calama'!D39 -> 0 | N37: ='AEX Calama'!D40 -> 0
B38: Arauco Express Recoleta | C38: StripCenter | D38: ='AEX Recoleta'!D43 -> 0 | E38: ='AEX Recoleta'!D44 -> 0 | F38: ='AEX Recoleta'!D45 -> 0 | G38: ='AEX Recoleta'!D46 -> 0 | H38: ='AEX Recoleta'!D47 -> 0 | I38: ='AEX Recoleta'!D48 -> 0 | J38: =SUM(D38:I38) -> 0 | L38: ='AEX Recoleta'!D38 -> 0 | M38: ='AEX Recoleta'!D39 -> 0 | N38: ='AEX Recoleta'!D40 -> 0
B39: Arauco Express Ciudad Empresarial II | C39: StripCenter | D39: ='AEX CE2'!D43 -> 0 | E39: ='AEX CE2'!D44 -> 0 | F39: ='AEX CE2'!D45 -> 0 | G39: ='AEX CE2'!D46 -> 0 | H39: ='AEX CE2'!D47 -> 0 | I39: ='AEX CE2'!D48 -> 0 | J39: =SUM(D39:I39) -> 0 | L39: ='AEX CE2'!D38 -> 0 | M39: ='AEX CE2'!D39 -> 0 | N39: ='AEX CE2'!D40 -> 0
B40: Arauco Express Las Brujas | C40: StripCenter | D40: ='AEX Las Brujas'!D43 -> 0 | E40: ='AEX Las Brujas'!D44 -> 0 | F40: ='AEX Las Brujas'!D45 -> 0 | G40: ='AEX Las Brujas'!D46 -> 0 | H40: ='AEX Las Brujas'!D47 -> 0 | I40: ='AEX Las Brujas'!D48 -> 0 | J40: =SUM(D40:I40) -> 0 | L40: ='AEX Las Brujas'!D38 -> 0 | M40: ='AEX Las Brujas'!D39 -> 0 | N40: ='AEX Las Brujas'!D40 -> 0

Sheet Parque Arauco Shopping Center
C2: CENTRO COMERCIAL: | D2: Parque Arauco Shopping Center
B4: Ítem | C4: Descripción del Bien o Servicio | D4: Descripción | J4: VALORES EN UF
B5: 1.0 | C5: CAPEX: NIVEL 1 - EQUIPOS DE MEDICIÓN EN CAMPO | D5: MEDIDA | E5: MARCA | F5: MODELO | G5: Cantidad | H5: P. Unitario (Neto) | J5: P. Total (Neto)
B6: 46023 | C6: Medidores Eléctricos Básicos (Medición directa, baja/media potencia, ej: PAC 1651) | D6: Un | H6: 0 | J6: =G6*H6 -> 0
B7: 46054 | C7: Medidores Eléctricos Avanzados (Mayor granularidad/calidad de energía, ej: PAC 1670) | D7: Un | H7: 0 | J7: =G7*H7 -> 0
B8: 1.3 | C8: Otros Medidores Electricos | Locales pequeños y aislados de red general (Modulos) | D8: Un | H8: 0 | J8: =G8*H8 -> 0
B9: 1.4 | C9: Otros Medidores Electricos | D9: Un | H9: 0 | J9: =G9*H9 -> 0
B10: 1.6 | C10: Accesorios de Medición (Transformadores de corriente, borneras, etc.) | D10: Gl | H10: 0 | J10: =G10*H10 -> 0
C11: TOTAL | J11: =SUM(J6:J10) -> 0
B12: 2.0 | C12: CAPEX: NIVEL 2 - SISTEMAS DE CONCENTRACIÓN Y PASARELAS | E12: MARCA | F12: MODELO | G12: Cantidad | H12: P. Unitario (Neto) | J12: P. Total (Neto)
B13: 46024 | C13: Concentradores/Gateways para Malls (Alta capacidad, Modbus RTU a TCP, ej: PAC 4220) | D13: Un | H13: 0 | J13: =G13*H13 -> 0
B14: 46055 | C14: Sistema Centralizado (Power Center) para Malls (Consolidación >200 puntos) | D14: Un | H14: 0 | J14: =G14*H14 -> 0
B15: 46083 | C15: Concentradores Locales Alternativos para Strip Centers (Solución simplificada/PLC) | D15: Un | H15: 0 | J15: =G15*H15 -> 0
C16: TOTAL | J16: =SUM(J13:J15) -> 0
B17: 3.0 | C17: CAPEX: NIVEL 3 - ARQUITECTURA DE COMUNICACIONES Y TABLEROS | E17: MARCA | F17: MODELO | G17: Cantidad | H17: P. Unitario (Neto) | J17: P. Total (Neto)
B18: 46025 | C18: Nodos Inalámbricos / Enlaces (Ej: Gateways LoRa para zonas sin cableado) | D18: Un | H18: 0 | J18: =G18*H18 -> 0
B19: 46056 | C19: Equipamiento de Red (Switches gestionables) | D19: Un | H19: 0 | J19: =G19*H19 -> 0
B20: 46084 | C20: Conversores de Medios (Ej: Serial a Ethernet, Cobre a Fibra) | D20: M | H20: 0 | J20: =G20*H20 -> 0
B21: 46115 | C21: Cobre o fibra | H21: 0 | J21: =G21*H21 -> 0
B22: 46145 | C22: Tableros de Comunicación y Concentración de Datos (Armado, gabinete, protecciones) | D22: Un | H22: 0 | J22: =G22*H22 -> 0
B23: 3.6 | C23: Materiales de Conectividad (Cable RS-485, Patchcords, Ferretería menor) | D23: Gl | H23: 0 | J23: =G23*H23 -> 0
C24: TOTAL | J24: =SUM(J18:J23) -> 0
B25: 4.0 | C25: SERVICIOS: INSTALACIÓN, INTEGRACIÓN Y PUESTA EN MARCHA | E25: MARCA | F25: MODELO | G25: Cantidad | H25: P. Unitario (Neto) | J25: P. Total (Neto)
B26: 46026 | C26: Desmontaje de medidores existentes e instalación de nuevos equipos | D26: Gl | H26: 0 | J26: =G26*H26 -> 0
B27: 46057 | C27: Tendido de cableado (Nivel de campo y enlace a Backbone PA) | D27: MT | H27: 0 | J27: =G27*H27 -> 0
B28: 46085 | C28: Configuración de Red, Asignación IP y Protocolos (Modbus RTU/TCP, MQTT) | D28: Gl | H28: 0 | J28: =G28*H28 -> 0
B29: 46116 | C29: Integración con Plataforma IoT/Cloud y Pruebas de Comunicación (Puesta en marcha) | D29: Gl | H29: 0 | J29: =G29*H29 -> 0
C30: TOTAL | J30: =SUM(J26:J29) -> 0
B31: 5.0 | C31: OPEX: PLATAFORMA, LICENCIAS | G31: Cantidad | H31: P. Unitario (Neto) | J31: P. Total (Neto)
B32: 46027 | C32: Licencia Anual Plataforma Cloud de Gestión Energética (Punto) | D32: Anual | G32: 1 | H32: 0 | J32: =G32*H32 -> 0 | K32: Costo de licenciamiento por medidor
C33: TOTAL | J33: =SUM(J32) -> 0
B34: 6.0 | C34: OPEX: MANTENCIÓN | G34: Cantidad | H34: P. Unitario (Neto) | J34: P. Total (Neto)
B35: 46028 | C35: Rutina de Mantenimiento Anual | D35: Anual | G35: 1 | H35: 0 | J35: =G35*H35 -> 0 | K35: Debe ceñirse a la rutina definida en BTG. No otra
C36: TOTAL | J36: =SUM(J35) -> 0
C38: HABILITACIÓN DE NUEVO PUNTO | D38: =SUM(D43:D47)/G32 -> 0
C39: MANTENCIÓN NUEVO PUNTO | D39: =H35 -> 0
C40: USO DE SOFTWARE POR NUEVO PUNTO | D40: =H32 -> 0
C42: RESUMEN
C43: CAPEX: NIVEL 1 - EQUIPOS DE MEDICIÓN EN CAMPO | D43: =J11 -> 0
C44: CAPEX: NIVEL 2 - SISTEMAS DE CONCENTRACIÓN Y PASARELAS | D44: =J16 -> 0
...

Sheet Parque Arauco Oriente
C2: CENTRO COMERCIAL: | D2: Parque Arauco Oriente
B4: Ítem | C4: Descripción del Bien o Servicio | D4: Descripción | J4: VALORES EN UF
B5: 1.0 | C5: CAPEX: NIVEL 1 - EQUIPOS DE MEDICIÓN EN CAMPO | D5: MEDIDA | E5: MARCA | F5: MODELO | G5: Cantidad | H5: P. Unitario (Neto) | J5: P. Total (Neto)
B6: 46023 | C6: Medidores Eléctricos Básicos (Medición directa, baja/media potencia, ej: PAC 1651) | D6: Un | H6: 0 | J6: =G6*H6 -> 0
B7: 46054 | C7: Medidores Eléctricos Avanzados (Mayor granularidad/calidad de energía, ej: PAC 1670) | D7: Un | H7: 0 | J7: =G7*H7 -> 0
B8: 1.3 | C8: Otros Medidores Electricos | Locales pequeños y aislados de red general (Modulos) | D8: Un | H8: 0 | J8: =G8*H8 -> 0
B9: 1.4 | C9: Otros Medidores Electricos | D9: Un | H9: 0 | J9: =G9*H9 -> 0
B10: 1.6 | C10: Accesorios de Medición (Transformadores de corriente, borneras, etc.) | D10: Gl | H10: 0 | J10: =G10*H10 -> 0
C11: TOTAL | J11: =SUM(J6:J10) -> 0
B12: 2.0 | C12: CAPEX: NIVEL 2 - SISTEMAS DE CONCENTRACIÓN Y PASARELAS | E12: MARCA | F12: MODELO | G12: Cantidad | H12: P. Unitario (Neto) | J12: P. Total (Neto)
B13: 46024 | C13: Concentradores/Gateways para Malls (Alta capacidad, Modbus RTU a TCP, ej: PAC 4220) | D13: Un | H13: 0 | J13: =G13*H13 -> 0
B14: 46055 | C14: Sistema Centralizado (Power Center) para Malls (Consolidación >200 puntos) | D14: Un | H14: 0 | J14: =G14*H14 -> 0
B15: 46083 | C15: Concentradores Locales Alternativos para Strip Centers (Solución simplificada/PLC) | D15: Un | H15: 0 | J15: =G15*H15 -> 0
C16: TOTAL | J16: =SUM(J13:J15) -> 0
B17: 3.0 | C17: CAPEX: NIVEL 3 - ARQUITECTURA DE COMUNICACIONES Y TABLEROS | E17: MARCA | F17: MODELO | G17: Cantidad | H17: P. Unitario (Neto) | J17: P. Total (Neto)
B18: 46025 | C18: Nodos Inalámbricos / Enlaces (Ej: Gateways LoRa para zonas sin cableado) | D18: Un | H18: 0 | J18: =G18*H18 -> 0
B19: 46056 | C19: Equipamiento de Red (Switches gestionables) | D19: Un | H19: 0 | J19: =G19*H19 -> 0
B20: 46084 | C20: Conversores de Medios (Ej: Serial a Ethernet, Cobre a Fibra) | D20: M | H20: 0 | J20: =G20*H20 -> 0
B21: 46115 | C21: Cobre o fibra | H21: 0 | J21: =G21*H21 -> 0
B22: 46145 | C22: Tableros de Comunicación y Concentración de Datos (Armado, gabinete, protecciones) | D22: Un | H22: 0 | J22: =G22*H22 -> 0
B23: 3.6 | C23: Materiales de Conectividad (Cable RS-485, Patchcords, Ferretería menor) | D23: Gl | H23: 0 | J23: =G23*H23 -> 0
C24: TOTAL | J24: =SUM(J18:J23) -> 0
B25: 4.0 | C25: SERVICIOS: INSTALACIÓN, INTEGRACIÓN Y PUESTA EN MARCHA | E25: MARCA | F25: MODELO | G25: Cantidad | H25: P. Unitario (Neto) | J25: P. Total (Neto)
B26: 46026 | C26: Desmontaje de medidores existentes e instalación de nuevos equipos | D26: Gl | H26: 0 | J26: =G26*H26 -> 0
B27: 46057 | C27: Tendido de cableado (Nivel de campo y enlace a Backbone PA) | D27: MT | H27: 0 | J27: =G27*H27 -> 0
B28: 46085 | C28: Configuración de Red, Asignación IP y Protocolos (Modbus RTU/TCP, MQTT) | D28: Gl | H28: 0 | J28: =G28*H28 -> 0
B29: 46116 | C29: Integración con Plataforma IoT/Cloud y Pruebas de Comunicación (Puesta en marcha) | D29: Gl | H29: 0 | J29: =G29*H29 -> 0
C30: TOTAL | J30: =SUM(J26:J29) -> 0
B31: 5.0 | C31: OPEX: PLATAFORMA, LICENCIAS | G31: Cantidad | H31: P. Unitario (Neto) | J31: P. Total (Neto)
B32: 46027 | C32: Licencia Anual Plataforma Cloud de Gestión Energética (Punto) | D32: Anual | G32: 1 | H32: 0 | J32: =G32*H32 -> 0 | K32: Costo de licenciamiento por medidor
C33: TOTAL | J33: =SUM(J32) -> 0
B34: 6.0 | C34: OPEX: MANTENCIÓN | G34: Cantidad | H34: P. Unitario (Neto) | J34: P. Total (Neto)
B35: 46028 | C35: Rutina de Mantenimiento Anual | D35: Anual | G35: 1 | H35: 0 | J35: =G35*H35 -> 0 | K35: Debe ceñirse a la rutina definida en BTG. No otra
C36: TOTAL | J36: =SUM(J35) -> 0
C38: HABILITACIÓN DE NUEVO PUNTO | D38: =SUM(D43:D47)/G32 -> 0
C39: MANTENCIÓN NUEVO PUNTO | D39: =H35 -> 0
C40: USO DE SOFTWARE POR NUEVO PUNTO | D40: =H32 -> 0
C42: RESUMEN
C43: CAPEX: NIVEL 1 - EQUIPOS DE MEDICIÓN EN CAMPO | D43: =J11 -> 0
C44: CAPEX: NIVEL 2 - SISTEMAS DE CONCENTRACIÓN Y PASARELAS | D44: =J16 -> 0
...

Sheet Arauco Maipú
C2: CENTRO COMERCIAL: | D2: Arauco Maipú
B4: Ítem | C4: Descripción del Bien o Servicio | D4: Descripción | J4: VALORES EN UF
B5: 1.0 | C5: CAPEX: NIVEL 1 - EQUIPOS DE MEDICIÓN EN CAMPO | D5: MEDIDA | E5: MARCA | F5: MODELO | G5: Cantidad | H5: P. Unitario (Neto) | J5: P. Total (Neto)
B6: 46023 | C6: Medidores Eléctricos Básicos (Medición directa, baja/media potencia, ej: PAC 1651) | D6: Un | H6: 0 | J6: =G6*H6 -> 0
B7: 46054 | C7: Medidores Eléctricos Avanzados (Mayor granularidad/calidad de energía, ej: PAC 1670) | D7: Un | H7: 0 | J7: =G7*H7 -> 0
B8: 1.3 | C8: Otros Medidores Electricos | Locales pequeños y aislados de red general (Modulos) | D8: Un | H8: 0 | J8: =G8*H8 -> 0
B9: 1.4 | C9: Otros Medidores Electricos | D9: Un | H9: 0 | J9: =G9*H9 -> 0
B10: 1.6 | C10: Accesorios de Medición (Transformadores de corriente, borneras, etc.) | D10: Gl | H10: 0 | J10: =G10*H10 -> 0
C11: TOTAL | J11: =SUM(J6:J10) -> 0
B12: 2.0 | C12: CAPEX: NIVEL 2 - SISTEMAS DE CONCENTRACIÓN Y PASARELAS | E12: MARCA | F12: MODELO | G12: Cantidad | H12: P. Unitario (Neto) | J12: P. Total (Neto)
B13: 46024 | C13: Concentradores/Gateways para Malls (Alta capacidad, Modbus RTU a TCP, ej: PAC 4220) | D13: Un | H13: 0 | J13: =G13*H13 -> 0
B14: 46055 | C14: Sistema Centralizado (Power Center) para Malls (Consolidación >200 puntos) | D14: Un | H14: 0 | J14: =G14*H14 -> 0
B15: 46083 | C15: Concentradores Locales Alternativos para Strip Centers (Solución simplificada/PLC) | D15: Un | H15: 0 | J15: =G15*H15 -> 0
C16: TOTAL | J16: =SUM(J13:J15) -> 0
B17: 3.0 | C17: CAPEX: NIVEL 3 - ARQUITECTURA DE COMUNICACIONES Y TABLEROS | E17: MARCA | F17: MODELO | G17: Cantidad | H17: P. Unitario (Neto) | J17: P. Total (Neto)
B18: 46025 | C18: Nodos Inalámbricos / Enlaces (Ej: Gateways LoRa para zonas sin cableado) | D18: Un | H18: 0 | J18: =G18*H18 -> 0
B19: 46056 | C19: Equipamiento de Red (Switches gestionables) | D19: Un | H19: 0 | J19: =G19*H19 -> 0
B20: 46084 | C20: Conversores de Medios (Ej: Serial a Ethernet, Cobre a Fibra) | D20: M | H20: 0 | J20: =G20*H20 -> 0
B21: 46115 | C21: Cobre o fibra | H21: 0 | J21: =G21*H21 -> 0
B22: 46145 | C22: Tableros de Comunicación y Concentración de Datos (Armado, gabinete, protecciones) | D22: Un | H22: 0 | J22: =G22*H22 -> 0
B23: 3.6 | C23: Materiales de Conectividad (Cable RS-485, Patchcords, Ferretería menor) | D23: Gl | H23: 0 | J23: =G23*H23 -> 0
C24: TOTAL | J24: =SUM(J18:J23) -> 0
B25: 4.0 | C25: SERVICIOS: INSTALACIÓN, INTEGRACIÓN Y PUESTA EN MARCHA | E25: MARCA | F25: MODELO | G25: Cantidad | H25: P. Unitario (Neto) | J25: P. Total (Neto)
B26: 46026 | C26: Desmontaje de medidores existentes e instalación de nuevos equipos | D26: Gl | H26: 0 | J26: =G26*H26 -> 0
B27: 46057 | C27: Tendido de cableado (Nivel de campo y enlace a Backbone PA) | D27: MT | H27: 0 | J27: =G27*H27 -> 0
B28: 46085 | C28: Configuración de Red, Asignación IP y Protocolos (Modbus RTU/TCP, MQTT) | D28: Gl | H28: 0 | J28: =G28*H28 -> 0
B29: 46116 | C29: Integración con Plataforma IoT/Cloud y Pruebas de Comunicación (Puesta en marcha) | D29: Gl | H29: 0 | J29: =G29*H29 -> 0
C30: TOTAL | J30: =SUM(J26:J29) -> 0
B31: 5.0 | C31: OPEX: PLATAFORMA, LICENCIAS | G31: Cantidad | H31: P. Unitario (Neto) | J31: P. Total (Neto)
B32: 46027 | C32: Licencia Anual Plataforma Cloud de Gestión Energética (Punto) | D32: Anual | G32: 1 | H32: 0 | J32: =G32*H32 -> 0 | K32: Costo de licenciamiento por medidor
C33: TOTAL | J33: =SUM(J32) -> 0
B34: 6.0 | C34: OPEX: MANTENCIÓN | G34: Cantidad | H34: P. Unitario (Neto) | J34: P. Total (Neto)
B35: 46028 | C35: Rutina de Mantenimiento Anual | D35: Anual | G35: 1 | H35: 0 | J35: =G35*H35 -> 0 | K35: Debe ceñirse a la rutina definida en BTG. No otra
C36: TOTAL | J36: =SUM(J35) -> 0
C38: HABILITACIÓN DE NUEVO PUNTO | D38: =SUM(D43:D47)/G32 -> 0
C39: MANTENCIÓN NUEVO PUNTO | D39: =H35 -> 0
C40: USO DE SOFTWARE POR NUEVO PUNTO | D40: =H32 -> 0
C42: RESUMEN
C43: CAPEX: NIVEL 1 - EQUIPOS DE MEDICIÓN EN CAMPO | D43: =J11 -> 0
C44: CAPEX: NIVEL 2 - SISTEMAS DE CONCENTRACIÓN Y PASARELAS | D44: =J16 -> 0
...

Sheet Arauco Estación
C2: CENTRO COMERCIAL: | D2: Arauco Estación
B4: Ítem | C4: Descripción del Bien o Servicio | D4: Descripción | J4: VALORES EN UF
B5: 1.0 | C5: CAPEX: NIVEL 1 - EQUIPOS DE MEDICIÓN EN CAMPO | D5: MEDIDA | E5: MARCA | F5: MODELO | G5: Cantidad | H5: P. Unitario (Neto) | J5: P. Total (Neto)
B6: 46023 | C6: Medidores Eléctricos Básicos (Medición directa, baja/media potencia, ej: PAC 1651) | D6: Un | H6: 0 | J6: =G6*H6 -> 0
B7: 46054 | C7: Medidores Eléctricos Avanzados (Mayor granularidad/calidad de energía, ej: PAC 1670) | D7: Un | H7: 0 | J7: =G7*H7 -> 0
B8: 1.3 | C8: Otros Medidores Electricos | Locales pequeños y aislados de red general (Modulos) | D8: Un | H8: 0 | J8: =G8*H8 -> 0
B9: 1.4 | C9: Otros Medidores Electricos | D9: Un | H9: 0 | J9: =G9*H9 -> 0
B10: 1.6 | C10: Accesorios de Medición (Transformadores de corriente, borneras, etc.) | D10: Gl | H10: 0 | J10: =G10*H10 -> 0
C11: TOTAL | J11: =SUM(J6:J10) -> 0
B12: 2.0 | C12: CAPEX: NIVEL 2 - SISTEMAS DE CONCENTRACIÓN Y PASARELAS | E12: MARCA | F12: MODELO | G12: Cantidad | H12: P. Unitario (Neto) | J12: P. Total (Neto)
B13: 46024 | C13: Concentradores/Gateways para Malls (Alta capacidad, Modbus RTU a TCP, ej: PAC 4220) | D13: Un | H13: 0 | J13: =G13*H13 -> 0
B14: 46055 | C14: Sistema Centralizado (Power Center) para Malls (Consolidación >200 puntos) | D14: Un | H14: 0 | J14: =G14*H14 -> 0
B15: 46083 | C15: Concentradores Locales Alternativos para Strip Centers (Solución simplificada/PLC) | D15: Un | H15: 0 | J15: =G15*H15 -> 0
C16: TOTAL | J16: =SUM(J13:J15) -> 0
B17: 3.0 | C17: CAPEX: NIVEL 3 - ARQUITECTURA DE COMUNICACIONES Y TABLEROS | E17: MARCA | F17: MODELO | G17: Cantidad | H17: P. Unitario (Neto) | J17: P. Total (Neto)
B18: 46025 | C18: Nodos Inalámbricos / Enlaces (Ej: Gateways LoRa para zonas sin cableado) | D18: Un | H18: 0 | J18: =G18*H18 -> 0
B19: 46056 | C19: Equipamiento de Red (Switches gestionables) | D19: Un | H19: 0 | J19: =G19*H19 -> 0
B20: 46084 | C20: Conversores de Medios (Ej: Serial a Ethernet, Cobre a Fibra) | D20: M | H20: 0 | J20: =G20*H20 -> 0
B21: 46115 | C21: Cobre o fibra | H21: 0 | J21: =G21*H21 -> 0
B22: 46145 | C22: Tableros de Comunicación y Concentración de Datos (Armado, gabinete, protecciones) | D22: Un | H22: 0 | J22: =G22*H22 -> 0
B23: 3.6 | C23: Materiales de Conectividad (Cable RS-485, Patchcords, Ferretería menor) | D23: Gl | H23: 0 | J23: =G23*H23 -> 0
C24: TOTAL | J24: =SUM(J18:J23) -> 0
B25: 4.0 | C25: SERVICIOS: INSTALACIÓN, INTEGRACIÓN Y PUESTA EN MARCHA | E25: MARCA | F25: MODELO | G25: Cantidad | H25: P. Unitario (Neto) | J25: P. Total (Neto)
B26: 46026 | C26: Desmontaje de medidores existentes e instalación de nuevos equipos | D26: Gl | H26: 0 | J26: =G26*H26 -> 0
B27: 46057 | C27: Tendido de cableado (Nivel de campo y enlace a Backbone PA) | D27: MT | H27: 0 | J27: =G27*H27 -> 0
B28: 46085 | C28: Configuración de Red, Asignación IP y Protocolos (Modbus RTU/TCP, MQTT) | D28: Gl | H28: 0 | J28: =G28*H28 -> 0
B29: 46116 | C29: Integración con Plataforma IoT/Cloud y Pruebas de Comunicación (Puesta en marcha) | D29: Gl | H29: 0 | J29: =G29*H29 -> 0
C30: TOTAL | J30: =SUM(J26:J29) -> 0
B31: 5.0 | C31: OPEX: PLATAFORMA, LICENCIAS | G31: Cantidad | H31: P. Unitario (Neto) | J31: P. Total (Neto)
B32: 46027 | C32: Licencia Anual Plataforma Cloud de Gestión Energética (Punto) | D32: Anual | G32: 1 | H32: 0 | J32: =G32*H32 -> 0 | K32: Costo de licenciamiento por medidor
C33: TOTAL | J33: =SUM(J32) -> 0
B34: 6.0 | C34: OPEX: MANTENCIÓN | G34: Cantidad | H34: P. Unitario (Neto) | J34: P. Total (Neto)
B35: 46028 | C35: Rutina de Mantenimiento Anual | D35: Anual | G35: 1 | H35: 0 | J35: =G35*H35 -> 0 | K35: Debe ceñirse a la rutina definida en BTG. No otra
C36: TOTAL | J36: =SUM(J35) -> 0
C38: HABILITACIÓN DE NUEVO PUNTO | D38: =SUM(D43:D47)/G32 -> 0
C39: MANTENCIÓN NUEVO PUNTO | D39: =H35 -> 0
C40: USO DE SOFTWARE POR NUEVO PUNTO | D40: =H32 -> 0
C42: RESUMEN
C43: CAPEX: NIVEL 1 - EQUIPOS DE MEDICIÓN EN CAMPO | D43: =J11 -> 0
C44: CAPEX: NIVEL 2 - SISTEMAS DE CONCENTRACIÓN Y PASARELAS | D44: =J16 -> 0
...

Sheet Arauco San Antonio
C2: CENTRO COMERCIAL: | D2: Arauco San Antonio
B4: Ítem | C4: Descripción del Bien o Servicio | D4: Descripción | J4: VALORES EN UF
B5: 1.0 | C5: CAPEX: NIVEL 1 - EQUIPOS DE MEDICIÓN EN CAMPO | D5: MEDIDA | E5: MARCA | F5: MODELO | G5: Cantidad | H5: P. Unitario (Neto) | J5: P. Total (Neto)
B6: 46023 | C6: Medidores Eléctricos Básicos (Medición directa, baja/media potencia, ej: PAC 1651) | D6: Un | H6: 0 | J6: =G6*H6 -> 0
B7: 46054 | C7: Medidores Eléctricos Avanzados (Mayor granularidad/calidad de energía, ej: PAC 1670) | D7: Un | H7: 0 | J7: =G7*H7 -> 0
B8: 1.3 | C8: Otros Medidores Electricos | Locales pequeños y aislados de red general (Modulos) | D8: Un | H8: 0 | J8: =G8*H8 -> 0
B9: 1.4 | C9: Otros Medidores Electricos | D9: Un | H9: 0 | J9: =G9*H9 -> 0
B10: 1.6 | C10: Accesorios de Medición (Transformadores de corriente, borneras, etc.) | D10: Gl | H10: 0 | J10: =G10*H10 -> 0
C11: TOTAL | J11: =SUM(J6:J10) -> 0
B12: 2.0 | C12: CAPEX: NIVEL 2 - SISTEMAS DE CONCENTRACIÓN Y PASARELAS | E12: MARCA | F12: MODELO | G12: Cantidad | H12: P. Unitario (Neto) | J12: P. Total (Neto)
B13: 46024 | C13: Concentradores/Gateways para Malls (Alta capacidad, Modbus RTU a TCP, ej: PAC 4220) | D13: Un | H13: 0 | J13: =G13*H13 -> 0
B14: 46055 | C14: Sistema Centralizado (Power Center) para Malls (Consolidación >200 puntos) | D14: Un | H14: 0 | J14: =G14*H14 -> 0
B15: 46083 | C15: Concentradores Locales Alternativos para Strip Centers (Solución simplificada/PLC) | D15: Un | H15: 0 | J15: =G15*H15 -> 0
C16: TOTAL | J16: =SUM(J13:J15) -> 0
B17: 3.0 | C17: CAPEX: NIVEL 3 - ARQUITECTURA DE COMUNICACIONES Y TABLEROS | E17: MARCA | F17: MODELO | G17: Cantidad | H17: P. Unitario (Neto) | J17: P. Total (Neto)
B18: 46025 | C18: Nodos Inalámbricos / Enlaces (Ej: Gateways LoRa para zonas sin cableado) | D18: Un | H18: 0 | J18: =G18*H18 -> 0
B19: 46056 | C19: Equipamiento de Red (Switches gestionables) | D19: Un | H19: 0 | J19: =G19*H19 -> 0
B20: 46084 | C20: Conversores de Medios (Ej: Serial a Ethernet, Cobre a Fibra) | D20: M | H20: 0 | J20: =G20*H20 -> 0
B21: 46115 | C21: Cobre o fibra | H21: 0 | J21: =G21*H21 -> 0
B22: 46145 | C22: Tableros de Comunicación y Concentración de Datos (Armado, gabinete, protecciones) | D22: Un | H22: 0 | J22: =G22*H22 -> 0
B23: 3.6 | C23: Materiales de Conectividad (Cable RS-485, Patchcords, Ferretería menor) | D23: Gl | H23: 0 | J23: =G23*H23 -> 0
C24: TOTAL | J24: =SUM(J18:J23) -> 0
B25: 4.0 | C25: SERVICIOS: INSTALACIÓN, INTEGRACIÓN Y PUESTA EN MARCHA | E25: MARCA | F25: MODELO | G25: Cantidad | H25: P. Unitario (Neto) | J25: P. Total (Neto)
B26: 46026 | C26: Desmontaje de medidores existentes e instalación de nuevos equipos | D26: Gl | H26: 0 | J26: =G26*H26 -> 0
B27: 46057 | C27: Tendido de cableado (Nivel de campo y enlace a Backbone PA) | D27: MT | H27: 0 | J27: =G27*H27 -> 0
B28: 46085 | C28: Configuración de Red, Asignación IP y Protocolos (Modbus RTU/TCP, MQTT) | D28: Gl | H28: 0 | J28: =G28*H28 -> 0
B29: 46116 | C29: Integración con Plataforma IoT/Cloud y Pruebas de Comunicación (Puesta en marcha) | D29: Gl | H29: 0 | J29: =G29*H29 -> 0
C30: TOTAL | J30: =SUM(J26:J29) -> 0
B31: 5.0 | C31: OPEX: PLATAFORMA, LICENCIAS | G31: Cantidad | H31: P. Unitario (Neto) | J31: P. Total (Neto)
B32: 46027 | C32: Licencia Anual Plataforma Cloud de Gestión Energética (Punto) | D32: Anual | G32: 1 | H32: 0 | J32: =G32*H32 -> 0 | K32: Costo de licenciamiento por medidor
C33: TOTAL | J33: =SUM(J32) -> 0
B34: 6.0 | C34: OPEX: MANTENCIÓN | G34: Cantidad | H34: P. Unitario (Neto) | J34: P. Total (Neto)
B35: 46028 | C35: Rutina de Mantenimiento Anual | D35: Anual | G35: 1 | H35: 0 | J35: =G35*H35 -> 0 | K35: Debe ceñirse a la rutina definida en BTG. No otra
C36: TOTAL | J36: =SUM(J35) -> 0
C38: HABILITACIÓN DE NUEVO PUNTO | D38: =SUM(D43:D47)/G32 -> 0
C39: MANTENCIÓN NUEVO PUNTO | D39: =H35 -> 0
C40: USO DE SOFTWARE POR NUEVO PUNTO | D40: =H32 -> 0
C42: RESUMEN
C43: CAPEX: NIVEL 1 - EQUIPOS DE MEDICIÓN EN CAMPO | D43: =J11 -> 0
C44: CAPEX: NIVEL 2 - SISTEMAS DE CONCENTRACIÓN Y PASARELAS | D44: =J16 -> 0
...

Sheet Arauco Chillán
C2: CENTRO COMERCIAL: | D2: Arauco Chillán
B4: Ítem | C4: Descripción del Bien o Servicio | D4: Descripción | J4: VALORES EN UF
B5: 1.0 | C5: CAPEX: NIVEL 1 - EQUIPOS DE MEDICIÓN EN CAMPO | D5: MEDIDA | E5: MARCA | F5: MODELO | G5: Cantidad | H5: P. Unitario (Neto) | J5: P. Total (Neto)
B6: 46023 | C6: Medidores Eléctricos Básicos (Medición directa, baja/media potencia, ej: PAC 1651) | D6: Un | H6: 0 | J6: =G6*H6 -> 0
B7: 46054 | C7: Medidores Eléctricos Avanzados (Mayor granularidad/calidad de energía, ej: PAC 1670) | D7: Un | H7: 0 | J7: =G7*H7 -> 0
B8: 1.3 | C8: Otros Medidores Electricos | Locales pequeños y aislados de red general (Modulos) | D8: Un | H8: 0 | J8: =G8*H8 -> 0
B9: 1.4 | C9: Otros Medidores Electricos | D9: Un | H9: 0 | J9: =G9*H9 -> 0
B10: 1.6 | C10: Accesorios de Medición (Transformadores de corriente, borneras, etc.) | D10: Gl | H10: 0 | J10: =G10*H10 -> 0
C11: TOTAL | J11: =SUM(J6:J10) -> 0
B12: 2.0 | C12: CAPEX: NIVEL 2 - SISTEMAS DE CONCENTRACIÓN Y PASARELAS | E12: MARCA | F12: MODELO | G12: Cantidad | H12: P. Unitario (Neto) | J12: P. Total (Neto)
B13: 46024 | C13: Concentradores/Gateways para Malls (Alta capacidad, Modbus RTU a TCP, ej: PAC 4220) | D13: Un | H13: 0 | J13: =G13*H13 -> 0
B14: 46055 | C14: Sistema Centralizado (Power Center) para Malls (Consolidación >200 puntos) | D14: Un | H14: 0 | J14: =G14*H14 -> 0
B15: 46083 | C15: Concentradores Locales Alternativos para Strip Centers (Solución simplificada/PLC) | D15: Un | H15: 0 | J15: =G15*H15 -> 0
C16: TOTAL | J16: =SUM(J13:J15) -> 0
B17: 3.0 | C17: CAPEX: NIVEL 3 - ARQUITECTURA DE COMUNICACIONES Y TABLEROS | E17: MARCA | F17: MODELO | G17: Cantidad | H17: P. Unitario (Neto) | J17: P. Total (Neto)
B18: 46025 | C18: Nodos Inalámbricos / Enlaces (Ej: Gateways LoRa para zonas sin cableado) | D18: Un | H18: 0 | J18: =G18*H18 -> 0
B19: 46056 | C19: Equipamiento de Red (Switches gestionables) | D19: Un | H19: 0 | J19: =G19*H19 -> 0
B20: 46084 | C20: Conversores de Medios (Ej: Serial a Ethernet, Cobre a Fibra) | D20: M | H20: 0 | J20: =G20*H20 -> 0
B21: 46115 | C21: Cobre o fibra | H21: 0 | J21: =G21*H21 -> 0
B22: 46145 | C22: Tableros de Comunicación y Concentración de Datos (Armado, gabinete, protecciones) | D22: Un | H22: 0 | J22: =G22*H22 -> 0
B23: 3.6 | C23: Materiales de Conectividad (Cable RS-485, Patchcords, Ferretería menor) | D23: Gl | H23: 0 | J23: =G23*H23 -> 0
C24: TOTAL | J24: =SUM(J18:J23) -> 0
B25: 4.0 | C25: SERVICIOS: INSTALACIÓN, INTEGRACIÓN Y PUESTA EN MARCHA | E25: MARCA | F25: MODELO | G25: Cantidad | H25: P. Unitario (Neto) | J25: P. Total (Neto)
B26: 46026 | C26: Desmontaje de medidores existentes e instalación de nuevos equipos | D26: Gl | H26: 0 | J26: =G26*H26 -> 0
B27: 46057 | C27: Tendido de cableado (Nivel de campo y enlace a Backbone PA) | D27: MT | H27: 0 | J27: =G27*H27 -> 0
B28: 46085 | C28: Configuración de Red, Asignación IP y Protocolos (Modbus RTU/TCP, MQTT) | D28: Gl | H28: 0 | J28: =G28*H28 -> 0
B29: 46116 | C29: Integración con Plataforma IoT/Cloud y Pruebas de Comunicación (Puesta en marcha) | D29: Gl | H29: 0 | J29: =G29*H29 -> 0
C30: TOTAL | J30: =SUM(J26:J29) -> 0
B31: 5.0 | C31: OPEX: PLATAFORMA, LICENCIAS | G31: Cantidad | H31: P. Unitario (Neto) | J31: P. Total (Neto)
B32: 46027 | C32: Licencia Anual Plataforma Cloud de Gestión Energética (Punto) | D32: Anual | G32: 1 | H32: 0 | J32: =G32*H32 -> 0 | K32: Costo de licenciamiento por medidor
C33: TOTAL | J33: =SUM(J32) -> 0
B34: 6.0 | C34: OPEX: MANTENCIÓN | G34: Cantidad | H34: P. Unitario (Neto) | J34: P. Total (Neto)
B35: 46028 | C35: Rutina de Mantenimiento Anual | D35: Anual | G35: 1 | H35: 0 | J35: =G35*H35 -> 0 | K35: Debe ceñirse a la rutina definida en BTG. No otra
C36: TOTAL | J36: =SUM(J35) -> 0
C38: HABILITACIÓN DE NUEVO PUNTO | D38: =SUM(D43:D47)/G32 -> 0
C39: MANTENCIÓN NUEVO PUNTO | D39: =H35 -> 0
C40: USO DE SOFTWARE POR NUEVO PUNTO | D40: =H32 -> 0
C42: RESUMEN
C43: CAPEX: NIVEL 1 - EQUIPOS DE MEDICIÓN EN CAMPO | D43: =J11 -> 0
C44: CAPEX: NIVEL 2 - SISTEMAS DE CONCENTRACIÓN Y PASARELAS | D44: =J16 -> 0
...

Sheet Arauco Coronel
C2: CENTRO COMERCIAL: | D2: Arauco Coronel
B4: Ítem | C4: Descripción del Bien o Servicio | D4: Descripción | J4: VALORES EN UF
B5: 1.0 | C5: CAPEX: NIVEL 1 - EQUIPOS DE MEDICIÓN EN CAMPO | D5: MEDIDA | E5: MARCA | F5: MODELO | G5: Cantidad | H5: P. Unitario (Neto) | J5: P. Total (Neto)
B6: 46023 | C6: Medidores Eléctricos Básicos (Medición directa, baja/media potencia, ej: PAC 1651) | D6: Un | H6: 0 | J6: =G6*H6 -> 0
B7: 46054 | C7: Medidores Eléctricos Avanzados (Mayor granularidad/calidad de energía, ej: PAC 1670) | D7: Un | H7: 0 | J7: =G7*H7 -> 0
B8: 1.3 | C8: Otros Medidores Electricos | Locales pequeños y aislados de red general (Modulos) | D8: Un | H8: 0 | J8: =G8*H8 -> 0
B9: 1.4 | C9: Otros Medidores Electricos | D9: Un | H9: 0 | J9: =G9*H9 -> 0
B10: 1.6 | C10: Accesorios de Medición (Transformadores de corriente, borneras, etc.) | D10: Gl | H10: 0 | J10: =G10*H10 -> 0
C11: TOTAL | J11: =SUM(J6:J10) -> 0
B12: 2.0 | C12: CAPEX: NIVEL 2 - SISTEMAS DE CONCENTRACIÓN Y PASARELAS | E12: MARCA | F12: MODELO | G12: Cantidad | H12: P. Unitario (Neto) | J12: P. Total (Neto)
B13: 46024 | C13: Concentradores/Gateways para Malls (Alta capacidad, Modbus RTU a TCP, ej: PAC 4220) | D13: Un | H13: 0 | J13: =G13*H13 -> 0
B14: 46055 | C14: Sistema Centralizado (Power Center) para Malls (Consolidación >200 puntos) | D14: Un | H14: 0 | J14: =G14*H14 -> 0
B15: 46083 | C15: Concentradores Locales Alternativos para Strip Centers (Solución simplificada/PLC) | D15: Un | H15: 0 | J15: =G15*H15 -> 0
C16: TOTAL | J16: =SUM(J13:J15) -> 0
B17: 3.0 | C17: CAPEX: NIVEL 3 - ARQUITECTURA DE COMUNICACIONES Y TABLEROS | E17: MARCA | F17: MODELO | G17: Cantidad | H17: P. Unitario (Neto) | J17: P. Total (Neto)
B18: 46025 | C18: Nodos Inalámbricos / Enlaces (Ej: Gateways LoRa para zonas sin cableado) | D18: Un | H18: 0 | J18: =G18*H18 -> 0
B19: 46056 | C19: Equipamiento de Red (Switches gestionables) | D19: Un | H19: 0 | J19: =G19*H19 -> 0
B20: 46084 | C20: Conversores de Medios (Ej: Serial a Ethernet, Cobre a Fibra) | D20: M | H20: 0 | J20: =G20*H20 -> 0
B21: 46115 | C21: Cobre o fibra | H21: 0 | J21: =G21*H21 -> 0
B22: 46145 | C22: Tableros de Comunicación y Concentración de Datos (Armado, gabinete, protecciones) | D22: Un | H22: 0 | J22: =G22*H22 -> 0
B23: 3.6 | C23: Materiales de Conectividad (Cable RS-485, Patchcords, Ferretería menor) | D23: Gl | H23: 0 | J23: =G23*H23 -> 0
C24: TOTAL | J24: =SUM(J18:J23) -> 0
B25: 4.0 | C25: SERVICIOS: INSTALACIÓN, INTEGRACIÓN Y PUESTA EN MARCHA | E25: MARCA | F25: MODELO | G25: Cantidad | H25: P. Unitario (Neto) | J25: P. Total (Neto)
B26: 46026 | C26: Desmontaje de medidores existentes e instalación de nuevos equipos | D26: Gl | H26: 0 | J26: =G26*H26 -> 0
B27: 46057 | C27: Tendido de cableado (Nivel de campo y enlace a Backbone PA) | D27: MT | H27: 0 | J27: =G27*H27 -> 0
B28: 46085 | C28: Configuración de Red, Asignación IP y Protocolos (Modbus RTU/TCP, MQTT) | D28: Gl | H28: 0 | J28: =G28*H28 -> 0
B29: 46116 | C29: Integración con Plataforma IoT/Cloud y Pruebas de Comunicación (Puesta en marcha) | D29: Gl | H29: 0 | J29: =G29*H29 -> 0
C30: TOTAL | J30: =SUM(J26:J29) -> 0
B31: 5.0 | C31: OPEX: PLATAFORMA, LICENCIAS | G31: Cantidad | H31: P. Unitario (Neto) | J31: P. Total (Neto)
B32: 46027 | C32: Licencia Anual Plataforma Cloud de Gestión Energética (Punto) | D32: Anual | G32: 1 | H32: 0 | J32: =G32*H32 -> 0 | K32: Costo de licenciamiento por medidor
C33: TOTAL | J33: =SUM(J32) -> 0
B34: 6.0 | C34: OPEX: MANTENCIÓN | G34: Cantidad | H34: P. Unitario (Neto) | J34: P. Total (Neto)
B35: 46028 | C35: Rutina de Mantenimiento Anual | D35: Anual | G35: 1 | H35: 0 | J35: =G35*H35 -> 0 | K35: Debe ceñirse a la rutina definida en BTG. No otra
C36: TOTAL | J36: =SUM(J35) -> 0
C38: HABILITACIÓN DE NUEVO PUNTO | D38: =SUM(D43:D47)/G32 -> 0
C39: MANTENCIÓN NUEVO PUNTO | D39: =H35 -> 0
C40: USO DE SOFTWARE POR NUEVO PUNTO | D40: =H32 -> 0
C42: RESUMEN
C43: CAPEX: NIVEL 1 - EQUIPOS DE MEDICIÓN EN CAMPO | D43: =J11 -> 0
C44: CAPEX: NIVEL 2 - SISTEMAS DE CONCENTRACIÓN Y PASARELAS | D44: =J16 -> 0
...

Sheet Parque Angamos
C2: CENTRO COMERCIAL: | D2: Parque Angamos
B4: Ítem | C4: Descripción del Bien o Servicio | D4: Descripción | J4: VALORES EN UF
B5: 1.0 | C5: CAPEX: NIVEL 1 - EQUIPOS DE MEDICIÓN EN CAMPO | D5: MEDIDA | E5: MARCA | F5: MODELO | G5: Cantidad | H5: P. Unitario (Neto) | J5: P. Total (Neto)
B6: 46023 | C6: Medidores Eléctricos Básicos (Medición directa, baja/media potencia, ej: PAC 1651) | D6: Un | H6: 0 | J6: =G6*H6 -> 0
B7: 46054 | C7: Medidores Eléctricos Avanzados (Mayor granularidad/calidad de energía, ej: PAC 1670) | D7: Un | H7: 0 | J7: =G7*H7 -> 0
B8: 1.3 | C8: Otros Medidores Electricos | Locales pequeños y aislados de red general (Modulos) | D8: Un | H8: 0 | J8: =G8*H8 -> 0
B9: 1.4 | C9: Otros Medidores Electricos | D9: Un | H9: 0 | J9: =G9*H9 -> 0
B10: 1.6 | C10: Accesorios de Medición (Transformadores de corriente, borneras, etc.) | D10: Gl | H10: 0 | J10: =G10*H10 -> 0
C11: TOTAL | J11: =SUM(J6:J10) -> 0
B12: 2.0 | C12: CAPEX: NIVEL 2 - SISTEMAS DE CONCENTRACIÓN Y PASARELAS | E12: MARCA | F12: MODELO | G12: Cantidad | H12: P. Unitario (Neto) | J12: P. Total (Neto)
B13: 46024 | C13: Concentradores/Gateways para Malls (Alta capacidad, Modbus RTU a TCP, ej: PAC 4220) | D13: Un | H13: 0 | J13: =G13*H13 -> 0
B14: 46055 | C14: Sistema Centralizado (Power Center) para Malls (Consolidación >200 puntos) | D14: Un | H14: 0 | J14: =G14*H14 -> 0
B15: 46083 | C15: Concentradores Locales Alternativos para Strip Centers (Solución simplificada/PLC) | D15: Un | H15: 0 | J15: =G15*H15 -> 0
C16: TOTAL | J16: =SUM(J13:J15) -> 0
B17: 3.0 | C17: CAPEX: NIVEL 3 - ARQUITECTURA DE COMUNICACIONES Y TABLEROS | E17: MARCA | F17: MODELO | G17: Cantidad | H17: P. Unitario (Neto) | J17: P. Total (Neto)
B18: 46025 | C18: Nodos Inalámbricos / Enlaces (Ej: Gateways LoRa para zonas sin cableado) | D18: Un | H18: 0 | J18: =G18*H18 -> 0
B19: 46056 | C19: Equipamiento de Red (Switches gestionables) | D19: Un | H19: 0 | J19: =G19*H19 -> 0
B20: 46084 | C20: Conversores de Medios (Ej: Serial a Ethernet, Cobre a Fibra) | D20: M | H20: 0 | J20: =G20*H20 -> 0
B21: 46115 | C21: Cobre o fibra | H21: 0 | J21: =G21*H21 -> 0
B22: 46145 | C22: Tableros de Comunicación y Concentración de Datos (Armado, gabinete, protecciones) | D22: Un | H22: 0 | J22: =G22*H22 -> 0
B23: 3.6 | C23: Materiales de Conectividad (Cable RS-485, Patchcords, Ferretería menor) | D23: Gl | H23: 0 | J23: =G23*H23 -> 0
C24: TOTAL | J24: =SUM(J18:J23) -> 0
B25: 4.0 | C25: SERVICIOS: INSTALACIÓN, INTEGRACIÓN Y PUESTA EN MARCHA | E25: MARCA | F25: MODELO | G25: Cantidad | H25: P. Unitario (Neto) | J25: P. Total (Neto)
B26: 46026 | C26: Desmontaje de medidores existentes e instalación de nuevos equipos | D26: Gl | H26: 0 | J26: =G26*H26 -> 0
B27: 46057 | C27: Tendido de cableado (Nivel de campo y enlace a Backbone PA) | D27: MT | H27: 0 | J27: =G27*H27 -> 0
B28: 46085 | C28: Configuración de Red, Asignación IP y Protocolos (Modbus RTU/TCP, MQTT) | D28: Gl | H28: 0 | J28: =G28*H28 -> 0
B29: 46116 | C29: Integración con Plataforma IoT/Cloud y Pruebas de Comunicación (Puesta en marcha) | D29: Gl | H29: 0 | J29: =G29*H29 -> 0
C30: TOTAL | J30: =SUM(J26:J29) -> 0
B31: 5.0 | C31: OPEX: PLATAFORMA, LICENCIAS | G31: Cantidad | H31: P. Unitario (Neto) | J31: P. Total (Neto)
B32: 46027 | C32: Licencia Anual Plataforma Cloud de Gestión Energética (Punto) | D32: Anual | G32: 1 | H32: 0 | J32: =G32*H32 -> 0 | K32: Costo de licenciamiento por medidor
C33: TOTAL | J33: =SUM(J32) -> 0
B34: 6.0 | C34: OPEX: MANTENCIÓN | G34: Cantidad | H34: P. Unitario (Neto) | J34: P. Total (Neto)
B35: 46028 | C35: Rutina de Mantenimiento Anual | D35: Anual | G35: 1 | H35: 0 | J35: =G35*H35 -> 0 | K35: Debe ceñirse a la rutina definida en BTG. No otra
C36: TOTAL | J36: =SUM(J35) -> 0
C38: HABILITACIÓN DE NUEVO PUNTO | D38: =SUM(D43:D47)/G32 -> 0
C39: MANTENCIÓN NUEVO PUNTO | D39: =H35 -> 0
C40: USO DE SOFTWARE POR NUEVO PUNTO | D40: =H32 -> 0
C42: RESUMEN
C43: CAPEX: NIVEL 1 - EQUIPOS DE MEDICIÓN EN CAMPO | D43: =J11 -> 0
C44: CAPEX: NIVEL 2 - SISTEMAS DE CONCENTRACIÓN Y PASARELAS | D44: =J16 -> 0
...

Sheet Parque Chicureo
C2: CENTRO COMERCIAL: | D2: Parque Chicureo
B4: Ítem | C4: Descripción del Bien o Servicio | D4: Descripción | J4: VALORES EN UF
B5: 1.0 | C5: CAPEX: NIVEL 1 - EQUIPOS DE MEDICIÓN EN CAMPO | D5: MEDIDA | E5: MARCA | F5: MODELO | G5: Cantidad | H5: P. Unitario (Neto) | J5: P. Total (Neto)
B6: 46023 | C6: Medidores Eléctricos Básicos (Medición directa, baja/media potencia, ej: PAC 1651) | D6: Un | H6: 0 | J6: =G6*H6 -> 0
B7: 46054 | C7: Medidores Eléctricos Avanzados (Mayor granularidad/calidad de energía, ej: PAC 1670) | D7: Un | H7: 0 | J7: =G7*H7 -> 0
B8: 1.3 | C8: Otros Medidores Electricos | Locales pequeños y aislados de red general (Modulos) | D8: Un | H8: 0 | J8: =G8*H8 -> 0
B9: 1.4 | C9: Otros Medidores Electricos | D9: Un | H9: 0 | J9: =G9*H9 -> 0
B10: 1.6 | C10: Accesorios de Medición (Transformadores de corriente, borneras, etc.) | D10: Gl | H10: 0 | J10: =G10*H10 -> 0
C11: TOTAL | J11: =SUM(J6:J10) -> 0
B12: 2.0 | C12: CAPEX: NIVEL 2 - SISTEMAS DE CONCENTRACIÓN Y PASARELAS | E12: MARCA | F12: MODELO | G12: Cantidad | H12: P. Unitario (Neto) | J12: P. Total (Neto)
B13: 46024 | C13: Concentradores/Gateways para Malls (Alta capacidad, Modbus RTU a TCP, ej: PAC 4220) | D13: Un | H13: 0 | J13: =G13*H13 -> 0
B14: 46055 | C14: Sistema Centralizado (Power Center) para Malls (Consolidación >200 puntos) | D14: Un | H14: 0 | J14: =G14*H14 -> 0
B15: 46083 | C15: Concentradores Locales Alternativos para Strip Centers (Solución simplificada/PLC) | D15: Un | H15: 0 | J15: =G15*H15 -> 0
C16: TOTAL | J16: =SUM(J13:J15) -> 0
B17: 3.0 | C17: CAPEX: NIVEL 3 - ARQUITECTURA DE COMUNICACIONES Y TABLEROS | E17: MARCA | F17: MODELO | G17: Cantidad | H17: P. Unitario (Neto) | J17: P. Total (Neto)
B18: 46025 | C18: Nodos Inalámbricos / Enlaces (Ej: Gateways LoRa para zonas sin cableado) | D18: Un | H18: 0 | J18: =G18*H18 -> 0
B19: 46056 | C19: Equipamiento de Red (Switches gestionables) | D19: Un | H19: 0 | J19: =G19*H19 -> 0
B20: 46084 | C20: Conversores de Medios (Ej: Serial a Ethernet, Cobre a Fibra) | D20: M | H20: 0 | J20: =G20*H20 -> 0
B21: 46115 | C21: Cobre o fibra | H21: 0 | J21: =G21*H21 -> 0
B22: 46145 | C22: Tableros de Comunicación y Concentración de Datos (Armado, gabinete, protecciones) | D22: Un | H22: 0 | J22: =G22*H22 -> 0
B23: 3.6 | C23: Materiales de Conectividad (Cable RS-485, Patchcords, Ferretería menor) | D23: Gl | H23: 0 | J23: =G23*H23 -> 0
C24: TOTAL | J24: =SUM(J18:J23) -> 0
B25: 4.0 | C25: SERVICIOS: INSTALACIÓN, INTEGRACIÓN Y PUESTA EN MARCHA | E25: MARCA | F25: MODELO | G25: Cantidad | H25: P. Unitario (Neto) | J25: P. Total (Neto)
B26: 46026 | C26: Desmontaje de medidores existentes e instalación de nuevos equipos | D26: Gl | H26: 0 | J26: =G26*H26 -> 0
B27: 46057 | C27: Tendido de cableado (Nivel de campo y enlace a Backbone PA) | D27: MT | H27: 0 | J27: =G27*H27 -> 0
B28: 46085 | C28: Configuración de Red, Asignación IP y Protocolos (Modbus RTU/TCP, MQTT) | D28: Gl | H28: 0 | J28: =G28*H28 -> 0
B29: 46116 | C29: Integración con Plataforma IoT/Cloud y Pruebas de Comunicación (Puesta en marcha) | D29: Gl | H29: 0 | J29: =G29*H29 -> 0
C30: TOTAL | J30: =SUM(J26:J29) -> 0
B31: 5.0 | C31: OPEX: PLATAFORMA, LICENCIAS | G31: Cantidad | H31: P. Unitario (Neto) | J31: P. Total (Neto)
B32: 46027 | C32: Licencia Anual Plataforma Cloud de Gestión Energética (Punto) | D32: Anual | G32: 1 | H32: 0 | J32: =G32*H32 -> 0 | K32: Costo de licenciamiento por medidor
C33: TOTAL | J33: =SUM(J32) -> 0
B34: 6.0 | C34: OPEX: MANTENCIÓN | G34: Cantidad | H34: P. Unitario (Neto) | J34: P. Total (Neto)
B35: 46028 | C35: Rutina de Mantenimiento Anual | D35: Anual | G35: 1 | H35: 0 | J35: =G35*H35 -> 0 | K35: Debe ceñirse a la rutina definida en BTG. No otra
C36: TOTAL | J36: =SUM(J35) -> 0
C38: HABILITACIÓN DE NUEVO PUNTO | D38: =SUM(D43:D47)/G32 -> 0
C39: MANTENCIÓN NUEVO PUNTO | D39: =H35 -> 0
C40: USO DE SOFTWARE POR NUEVO PUNTO | D40: =H32 -> 0
C42: RESUMEN
C43: CAPEX: NIVEL 1 - EQUIPOS DE MEDICIÓN EN CAMPO | D43: =J11 -> 0
C44: CAPEX: NIVEL 2 - SISTEMAS DE CONCENTRACIÓN Y PASARELAS | D44: =J16 -> 0
...

Sheet Arauco Quilicura
C2: CENTRO COMERCIAL: | D2: Arauco Quilicura
B4: Ítem | C4: Descripción del Bien o Servicio | D4: Descripción | J4: VALORES EN UF
B5: 1.0 | C5: CAPEX: NIVEL 1 - EQUIPOS DE MEDICIÓN EN CAMPO | D5: MEDIDA | E5: MARCA | F5: MODELO | G5: Cantidad | H5: P. Unitario (Neto) | J5: P. Total (Neto)
B6: 46023 | C6: Medidores Eléctricos Básicos (Medición directa, baja/media potencia, ej: PAC 1651) | D6: Un | H6: 0 | J6: =G6*H6 -> 0
B7: 46054 | C7: Medidores Eléctricos Avanzados (Mayor granularidad/calidad de energía, ej: PAC 1670) | D7: Un | H7: 0 | J7: =G7*H7 -> 0
B8: 1.3 | C8: Otros Medidores Electricos | Locales pequeños y aislados de red general (Modulos) | D8: Un | H8: 0 | J8: =G8*H8 -> 0
B9: 1.4 | C9: Otros Medidores Electricos | D9: Un | H9: 0 | J9: =G9*H9 -> 0
B10: 1.6 | C10: Accesorios de Medición (Transformadores de corriente, borneras, etc.) | D10: Gl | H10: 0 | J10: =G10*H10 -> 0
C11: TOTAL | J11: =SUM(J6:J10) -> 0
B12: 2.0 | C12: CAPEX: NIVEL 2 - SISTEMAS DE CONCENTRACIÓN Y PASARELAS | E12: MARCA | F12: MODELO | G12: Cantidad | H12: P. Unitario (Neto) | J12: P. Total (Neto)
B13: 46024 | C13: Concentradores/Gateways para Malls (Alta capacidad, Modbus RTU a TCP, ej: PAC 4220) | D13: Un | H13: 0 | J13: =G13*H13 -> 0
B14: 46055 | C14: Sistema Centralizado (Power Center) para Malls (Consolidación >200 puntos) | D14: Un | H14: 0 | J14: =G14*H14 -> 0
B15: 46083 | C15: Concentradores Locales Alternativos para Strip Centers (Solución simplificada/PLC) | D15: Un | H15: 0 | J15: =G15*H15 -> 0
C16: TOTAL | J16: =SUM(J13:J15) -> 0
B17: 3.0 | C17: CAPEX: NIVEL 3 - ARQUITECTURA DE COMUNICACIONES Y TABLEROS | E17: MARCA | F17: MODELO | G17: Cantidad | H17: P. Unitario (Neto) | J17: P. Total (Neto)
B18: 46025 | C18: Nodos Inalámbricos / Enlaces (Ej: Gateways LoRa para zonas sin cableado) | D18: Un | H18: 0 | J18: =G18*H18 -> 0
B19: 46056 | C19: Equipamiento de Red (Switches gestionables) | D19: Un | H19: 0 | J19: =G19*H19 -> 0
B20: 46084 | C20: Conversores de Medios (Ej: Serial a Ethernet, Cobre a Fibra) | D20: M | H20: 0 | J20: =G20*H20 -> 0
B21: 46115 | C21: Cobre o fibra | H21: 0 | J21: =G21*H21 -> 0
B22: 46145 | C22: Tableros de Comunicación y Concentración de Datos (Armado, gabinete, protecciones) | D22: Un | H22: 0 | J22: =G22*H22 -> 0
B23: 3.6 | C23: Materiales de Conectividad (Cable RS-485, Patchcords, Ferretería menor) | D23: Gl | H23: 0 | J23: =G23*H23 -> 0
C24: TOTAL | J24: =SUM(J18:J23) -> 0
B25: 4.0 | C25: SERVICIOS: INSTALACIÓN, INTEGRACIÓN Y PUESTA EN MARCHA | E25: MARCA | F25: MODELO | G25: Cantidad | H25: P. Unitario (Neto) | J25: P. Total (Neto)
B26: 46026 | C26: Desmontaje de medidores existentes e instalación de nuevos equipos | D26: Gl | H26: 0 | J26: =G26*H26 -> 0
B27: 46057 | C27: Tendido de cableado (Nivel de campo y enlace a Backbone PA) | D27: MT | H27: 0 | J27: =G27*H27 -> 0
B28: 46085 | C28: Configuración de Red, Asignación IP y Protocolos (Modbus RTU/TCP, MQTT) | D28: Gl | H28: 0 | J28: =G28*H28 -> 0
B29: 46116 | C29: Integración con Plataforma IoT/Cloud y Pruebas de Comunicación (Puesta en marcha) | D29: Gl | H29: 0 | J29: =G29*H29 -> 0
C30: TOTAL | J30: =SUM(J26:J29) -> 0
B31: 5.0 | C31: OPEX: PLATAFORMA, LICENCIAS | G31: Cantidad | H31: P. Unitario (Neto) | J31: P. Total (Neto)
B32: 46027 | C32: Licencia Anual Plataforma Cloud de Gestión Energética (Punto) | D32: Anual | G32: 1 | H32: 0 | J32: =G32*H32 -> 0 | K32: Costo de licenciamiento por medidor
C33: TOTAL | J33: =SUM(J32) -> 0
B34: 6.0 | C34: OPEX: MANTENCIÓN | G34: Cantidad | H34: P. Unitario (Neto) | J34: P. Total (Neto)
B35: 46028 | C35: Rutina de Mantenimiento Anual | D35: Anual | G35: 1 | H35: 0 | J35: =G35*H35 -> 0 | K35: Debe ceñirse a la rutina definida en BTG. No otra
C36: TOTAL | J36: =SUM(J35) -> 0
C38: HABILITACIÓN DE NUEVO PUNTO | D38: =SUM(D43:D47)/G32 -> 0
C39: MANTENCIÓN NUEVO PUNTO | D39: =H35 -> 0
C40: USO DE SOFTWARE POR NUEVO PUNTO | D40: =H32 -> 0
C42: RESUMEN
C43: CAPEX: NIVEL 1 - EQUIPOS DE MEDICIÓN EN CAMPO | D43: =J11 -> 0
C44: CAPEX: NIVEL 2 - SISTEMAS DE CONCENTRACIÓN Y PASARELAS | D44: =J16 -> 0
...

Sheet Arauco El Bosque
C2: CENTRO COMERCIAL: | D2: Arauco El Bosque
B4: Ítem | C4: Descripción del Bien o Servicio | D4: Descripción | J4: VALORES EN UF
B5: 1.0 | C5: CAPEX: NIVEL 1 - EQUIPOS DE MEDICIÓN EN CAMPO | D5: MEDIDA | E5: MARCA | F5: MODELO | G5: Cantidad | H5: P. Unitario (Neto) | J5: P. Total (Neto)
B6: 46023 | C6: Medidores Eléctricos Básicos (Medición directa, baja/media potencia, ej: PAC 1651) | D6: Un | H6: 0 | J6: =G6*H6 -> 0
B7: 46054 | C7: Medidores Eléctricos Avanzados (Mayor granularidad/calidad de energía, ej: PAC 1670) | D7: Un | H7: 0 | J7: =G7*H7 -> 0
B8: 1.3 | C8: Otros Medidores Electricos | Locales pequeños y aislados de red general (Modulos) | D8: Un | H8: 0 | J8: =G8*H8 -> 0
B9: 1.4 | C9: Otros Medidores Electricos | D9: Un | H9: 0 | J9: =G9*H9 -> 0
B10: 1.6 | C10: Accesorios de Medición (Transformadores de corriente, borneras, etc.) | D10: Gl | H10: 0 | J10: =G10*H10 -> 0
C11: TOTAL | J11: =SUM(J6:J10) -> 0
B12: 2.0 | C12: CAPEX: NIVEL 2 - SISTEMAS DE CONCENTRACIÓN Y PASARELAS | E12: MARCA | F12: MODELO | G12: Cantidad | H12: P. Unitario (Neto) | J12: P. Total (Neto)
B13: 46024 | C13: Concentradores/Gateways para Malls (Alta capacidad, Modbus RTU a TCP, ej: PAC 4220) | D13: Un | H13: 0 | J13: =G13*H13 -> 0
B14: 46055 | C14: Sistema Centralizado (Power Center) para Malls (Consolidación >200 puntos) | D14: Un | H14: 0 | J14: =G14*H14 -> 0
B15: 46083 | C15: Concentradores Locales Alternativos para Strip Centers (Solución simplificada/PLC) | D15: Un | H15: 0 | J15: =G15*H15 -> 0
C16: TOTAL | J16: =SUM(J13:J15) -> 0
B17: 3.0 | C17: CAPEX: NIVEL 3 - ARQUITECTURA DE COMUNICACIONES Y TABLEROS | E17: MARCA | F17: MODELO | G17: Cantidad | H17: P. Unitario (Neto) | J17: P. Total (Neto)
B18: 46025 | C18: Nodos Inalámbricos / Enlaces (Ej: Gateways LoRa para zonas sin cableado) | D18: Un | H18: 0 | J18: =G18*H18 -> 0
B19: 46056 | C19: Equipamiento de Red (Switches gestionables) | D19: Un | H19: 0 | J19: =G19*H19 -> 0
B20: 46084 | C20: Conversores de Medios (Ej: Serial a Ethernet, Cobre a Fibra) | D20: M | H20: 0 | J20: =G20*H20 -> 0
B21: 46115 | C21: Cobre o fibra | H21: 0 | J21: =G21*H21 -> 0
B22: 46145 | C22: Tableros de Comunicación y Concentración de Datos (Armado, gabinete, protecciones) | D22: Un | H22: 0 | J22: =G22*H22 -> 0
B23: 3.6 | C23: Materiales de Conectividad (Cable RS-485, Patchcords, Ferretería menor) | D23: Gl | H23: 0 | J23: =G23*H23 -> 0
C24: TOTAL | J24: =SUM(J18:J23) -> 0
B25: 4.0 | C25: SERVICIOS: INSTALACIÓN, INTEGRACIÓN Y PUESTA EN MARCHA | E25: MARCA | F25: MODELO | G25: Cantidad | H25: P. Unitario (Neto) | J25: P. Total (Neto)
B26: 46026 | C26: Desmontaje de medidores existentes e instalación de nuevos equipos | D26: Gl | H26: 0 | J26: =G26*H26 -> 0
B27: 46057 | C27: Tendido de cableado (Nivel de campo y enlace a Backbone PA) | D27: MT | H27: 0 | J27: =G27*H27 -> 0
B28: 46085 | C28: Configuración de Red, Asignación IP y Protocolos (Modbus RTU/TCP, MQTT) | D28: Gl | H28: 0 | J28: =G28*H28 -> 0
B29: 46116 | C29: Integración con Plataforma IoT/Cloud y Pruebas de Comunicación (Puesta en marcha) | D29: Gl | H29: 0 | J29: =G29*H29 -> 0
C30: TOTAL | J30: =SUM(J26:J29) -> 0
B31: 5.0 | C31: OPEX: PLATAFORMA, LICENCIAS | G31: Cantidad | H31: P. Unitario (Neto) | J31: P. Total (Neto)
B32: 46027 | C32: Licencia Anual Plataforma Cloud de Gestión Energética (Punto) | D32: Anual | G32: 1 | H32: 0 | J32: =G32*H32 -> 0 | K32: Costo de licenciamiento por medidor
C33: TOTAL | J33: =SUM(J32) -> 0
B34: 6.0 | C34: OPEX: MANTENCIÓN | G34: Cantidad | H34: P. Unitario (Neto) | J34: P. Total (Neto)
B35: 46028 | C35: Rutina de Mantenimiento Anual | D35: Anual | G35: 1 | H35: 0 | J35: =G35*H35 -> 0 | K35: Debe ceñirse a la rutina definida en BTG. No otra
C36: TOTAL | J36: =SUM(J35) -> 0
C38: HABILITACIÓN DE NUEVO PUNTO | D38: =SUM(D43:D47)/G32 -> 0
C39: MANTENCIÓN NUEVO PUNTO | D39: =H35 -> 0
C40: USO DE SOFTWARE POR NUEVO PUNTO | D40: =H32 -> 0
C42: RESUMEN
C43: CAPEX: NIVEL 1 - EQUIPOS DE MEDICIÓN EN CAMPO | D43: =J11 -> 0
C44: CAPEX: NIVEL 2 - SISTEMAS DE CONCENTRACIÓN Y PASARELAS | D44: =J16 -> 0
...

Sheet Outlet Buenaventura
C2: CENTRO COMERCIAL: | D2: Outlet Buenaventura
B4: Ítem | C4: Descripción del Bien o Servicio | D4: Descripción | J4: VALORES EN UF
B5: 1.0 | C5: CAPEX: NIVEL 1 - EQUIPOS DE MEDICIÓN EN CAMPO | D5: MEDIDA | E5: MARCA | F5: MODELO | G5: Cantidad | H5: P. Unitario (Neto) | J5: P. Total (Neto)
B6: 46023 | C6: Medidores Eléctricos Básicos (Medición directa, baja/media potencia, ej: PAC 1651) | D6: Un | H6: 0 | J6: =G6*H6 -> 0
B7: 46054 | C7: Medidores Eléctricos Avanzados (Mayor granularidad/calidad de energía, ej: PAC 1670) | D7: Un | H7: 0 | J7: =G7*H7 -> 0
B8: 1.3 | C8: Otros Medidores Electricos | Locales pequeños y aislados de red general (Modulos) | D8: Un | H8: 0 | J8: =G8*H8 -> 0
B9: 1.4 | C9: Otros Medidores Electricos | D9: Un | H9: 0 | J9: =G9*H9 -> 0
B10: 1.6 | C10: Accesorios de Medición (Transformadores de corriente, borneras, etc.) | D10: Gl | H10: 0 | J10: =G10*H10 -> 0
C11: TOTAL | J11: =SUM(J6:J10) -> 0
B12: 2.0 | C12: CAPEX: NIVEL 2 - SISTEMAS DE CONCENTRACIÓN Y PASARELAS | E12: MARCA | F12: MODELO | G12: Cantidad | H12: P. Unitario (Neto) | J12: P. Total (Neto)
B13: 46024 | C13: Concentradores/Gateways para Malls (Alta capacidad, Modbus RTU a TCP, ej: PAC 4220) | D13: Un | H13: 0 | J13: =G13*H13 -> 0
B14: 46055 | C14: Sistema Centralizado (Power Center) para Malls (Consolidación >200 puntos) | D14: Un | H14: 0 | J14: =G14*H14 -> 0
B15: 46083 | C15: Concentradores Locales Alternativos para Strip Centers (Solución simplificada/PLC) | D15: Un | H15: 0 | J15: =G15*H15 -> 0
C16: TOTAL | J16: =SUM(J13:J15) -> 0
B17: 3.0 | C17: CAPEX: NIVEL 3 - ARQUITECTURA DE COMUNICACIONES Y TABLEROS | E17: MARCA | F17: MODELO | G17: Cantidad | H17: P. Unitario (Neto) | J17: P. Total (Neto)
B18: 46025 | C18: Nodos Inalámbricos / Enlaces (Ej: Gateways LoRa para zonas sin cableado) | D18: Un | H18: 0 | J18: =G18*H18 -> 0
B19: 46056 | C19: Equipamiento de Red (Switches gestionables) | D19: Un | H19: 0 | J19: =G19*H19 -> 0
B20: 46084 | C20: Conversores de Medios (Ej: Serial a Ethernet, Cobre a Fibra) | D20: M | H20: 0 | J20: =G20*H20 -> 0
B21: 46115 | C21: Cobre o fibra | H21: 0 | J21: =G21*H21 -> 0
B22: 46145 | C22: Tableros de Comunicación y Concentración de Datos (Armado, gabinete, protecciones) | D22: Un | H22: 0 | J22: =G22*H22 -> 0
B23: 3.6 | C23: Materiales de Conectividad (Cable RS-485, Patchcords, Ferretería menor) | D23: Gl | H23: 0 | J23: =G23*H23 -> 0
C24: TOTAL | J24: =SUM(J18:J23) -> 0
B25: 4.0 | C25: SERVICIOS: INSTALACIÓN, INTEGRACIÓN Y PUESTA EN MARCHA | E25: MARCA | F25: MODELO | G25: Cantidad | H25: P. Unitario (Neto) | J25: P. Total (Neto)
B26: 46026 | C26: Desmontaje de medidores existentes e instalación de nuevos equipos | D26: Gl | H26: 0 | J26: =G26*H26 -> 0
B27: 46057 | C27: Tendido de cableado (Nivel de campo y enlace a Backbone PA) | D27: MT | H27: 0 | J27: =G27*H27 -> 0
B28: 46085 | C28: Configuración de Red, Asignación IP y Protocolos (Modbus RTU/TCP, MQTT) | D28: Gl | H28: 0 | J28: =G28*H28 -> 0
B29: 46116 | C29: Integración con Plataforma IoT/Cloud y Pruebas de Comunicación (Puesta en marcha) | D29: Gl | H29: 0 | J29: =G29*H29 -> 0
C30: TOTAL | J30: =SUM(J26:J29) -> 0
B31: 5.0 | C31: OPEX: PLATAFORMA, LICENCIAS | G31: Cantidad | H31: P. Unitario (Neto) | J31: P. Total (Neto)
B32: 46027 | C32: Licencia Anual Plataforma Cloud de Gestión Energética (Punto) | D32: Anual | G32: 1 | H32: 0 | J32: =G32*H32 -> 0 | K32: Costo de licenciamiento por medidor
C33: TOTAL | J33: =SUM(J32) -> 0
B34: 6.0 | C34: OPEX: MANTENCIÓN | G34: Cantidad | H34: P. Unitario (Neto) | J34: P. Total (Neto)
B35: 46028 | C35: Rutina de Mantenimiento Anual | D35: Anual | G35: 1 | H35: 0 | J35: =G35*H35 -> 0 | K35: Debe ceñirse a la rutina definida en BTG. No otra
C36: TOTAL | J36: =SUM(J35) -> 0
C38: HABILITACIÓN DE NUEVO PUNTO | D38: =SUM(D43:D47)/G32 -> 0
C39: MANTENCIÓN NUEVO PUNTO | D39: =H35 -> 0
C40: USO DE SOFTWARE POR NUEVO PUNTO | D40: =H32 -> 0
C42: RESUMEN
C43: CAPEX: NIVEL 1 - EQUIPOS DE MEDICIÓN EN CAMPO | D43: =J11 -> 0
C44: CAPEX: NIVEL 2 - SISTEMAS DE CONCENTRACIÓN Y PASARELAS | D44: =J16 -> 0
...

Sheet  Outlet Curauma
C2: CENTRO COMERCIAL: | D2: Outlet Curauma
